Workbook

Sheet MAT-CHINA
A1: PART | B1: T | C1: W | D1: L | E1: PCS | F1: INV | G1: IN DATE | H1: OUT DATE - JULY | AM1: BALANCE | AN1: m3 | AO1: USD/PCS | AP1: USD/m3 | AQ1: USD to THB
H2: 1 | I2: 2 | J2: 3 | K2: 4 | L2: 5 | M2: 6 | N2: 7 | O2: 8 | P2: 9 | Q2: 10 | R2: 11 | S2: 12 | T2: 13 | U2: 14 | V2: 15 | W2: 16 | X2: 17 | Y2: 18 | Z2: 19 | AA2: 20 | AB2: 21 | AC2: 22 | AD2: 23 | AE2: 24 | AF2: 25 | AG2: 26 | AH2: 27 | AI2: 28 | AJ2: 29 | AK2: 30 | AL2: 31
A3: 22122 | B3: 12.7 | C3: 57.2 | D3: 1219.2 | E3: 104 | F3: TGTM-25001 | G3: 45706 | AM3: =E3-H3-I3-J3-K3-L3-M3-N3-O3-P3-Q3-R3-S3-T3-U3-V3-W3-X3-Y3-Z3-AA3-AB3-AC3-AD3-AE3-AF3-AG3-AH3-AI3-AJ3-AK3-AL3 -> 104 | AN3: =B3*C3*D3*AM3/1000000000 -> 0.092110267 | AO3: 0.65 | AQ3: =AO3*AM3*34.3391 -> 2321.3232
A4: 22122 | B4: 12.7 | C4: 57.2 | D4: 1219.2 | E4: 120 | F4: TGTM-25003 | G4: 45744 | AM4: =E4-H4-I4-J4-K4-L4-M4-N4-O4-P4-Q4-R4-S4-T4-U4-V4-W4-X4-Y4-Z4-AA4-AB4-AC4-AD4-AE4-AF4-AG4-AH4-AI4-AJ4-AK4-AL4 -> 120 | AN4: =B4*C4*D4*AM4/1000000000 -> 0.10628108 | AO4: 0.647 | AQ4: =AO4*AM4*33.8617 -> 2629.0224
A5: 22123 | B5: 12.7 | C5: 82.55 | D5: 1219.2 | E5: 1092 | F5: SSI-2501 | G5: 46057 | AM5: =E5-H5-I5-J5-K5-L5-M5-N5-O5-P5-Q5-R5-S5-T5-U5-V5-W5-X5-Y5-Z5-AA5-AB5-AC5-AD5-AE5-AF5-AG5-AH5-AI5-AJ5-AK5-AL5 -> 1092 | AN5: =B5*C5*D5*AM5/1000000000 -> 1.3957846 | AP5: 650 | AQ5: =AN5*AP5*31.4666 -> 28548.386
A6: 22123 | B6: 12.7 | C6: 82.55 | D6: 1219.2 | E6: 202 | F6: SSI-2501 | G6: 46057 | AM6: =E6-H6-I6-J6-K6-L6-M6-N6-O6-P6-Q6-R6-S6-T6-U6-V6-W6-X6-Y6-Z6-AA6-AB6-AC6-AD6-AE6-AF6-AG6-AH6-AI6-AJ6-AK6-AL6 -> 202 | AN6: =B6*C6*D6*AM6/1000000000 -> 0.25819458 | AP6: 650 | AQ6: =AN6*AP6*31.4666 -> 5280.9286
A7: 22123 | B7: 12.7 | C7: 82.55 | D7: 1219.2 | E7: 1092 | F7: SSI-2501 | G7: 46057 | AM7: =E7-H7-I7-J7-K7-L7-M7-N7-O7-P7-Q7-R7-S7-T7-U7-V7-W7-X7-Y7-Z7-AA7-AB7-AC7-AD7-AE7-AF7-AG7-AH7-AI7-AJ7-AK7-AL7 -> 1092 | AN7: =B7*C7*D7*AM7/1000000000 -> 1.3957846 | AP7: 650 | AQ7: =AN7*AP7*31.4666 -> 28548.386
A8: 22123 | B8: 12.7 | C8: 82.55 | D8: 1219.2 | E8: 1092 | F8: SSI-2501 | G8: 46057 | AM8: =E8-H8-I8-J8-K8-L8-M8-N8-O8-P8-Q8-R8-S8-T8-U8-V8-W8-X8-Y8-Z8-AA8-AB8-AC8-AD8-AE8-AF8-AG8-AH8-AI8-AJ8-AK8-AL8 -> 1092 | AN8: =B8*C8*D8*AM8/1000000000 -> 1.3957846 | AP8: 650 | AQ8: =AN8*AP8*31.4666 -> 28548.386
A9: 22124 | B9: 12.7 | C9: 107.95 | D9: 1219.2 | E9: 700 | F9: SSI-2501 | G9: 46057 | AG9: 260 | AM9: =E9-H9-I9-J9-K9-L9-M9-N9-O9-P9-Q9-R9-S9-T9-U9-V9-W9-X9-Y9-Z9-AA9-AB9-AC9-AD9-AE9-AF9-AG9-AH9-AI9-AJ9-AK9-AL9 -> 440 | AN9: =B9*C9*D9*AM9/1000000000 -> 0.73545143 | AP9: 650 | AQ9: =AN9*AP9*31.4666 -> 15042.401
A10: 22124 | B10: 12.7 | C10: 108 | D10: 1219.2 | E10: 315 | F10: TGTM-25001 | G10: 45706 | AM10: =E10-H10-I10-J10-K10-L10-M10-N10-O10-P10-Q10-R10-S10-T10-U10-V10-W10-X10-Y10-Z10-AA10-AB10-AC10-AD10-AE10-AF10-AG10-AH10-AI10-AJ10-AK10-AL10 -> 315 | AN10: =B10*C10*D10*AM10/1000000000 -> 0.52676024 | AO10: 1.22 | AQ10: =AO10*AM10*34.3391 -> 13196.516
A11: 22124 | B11: 12.7 | C11: 108 | D11: 1219.2 | E11: 350 | F11: TGTM-25003 | G11: 45744 | AM11: =E11-H11-I11-J11-K11-L11-M11-N11-O11-P11-Q11-R11-S11-T11-U11-V11-W11-X11-Y11-Z11-AA11-AB11-AC11-AD11-AE11-AF11-AG11-AH11-AI11-AJ11-AK11-AL11 -> 350 | AN11: =B11*C11*D11*AM11/1000000000 -> 0.58528915 | AO11: 1.221 | AQ11: =AO11*AM11*33.8617 -> 14470.797
A12: 22125 | B12: 12.7 | C12: 158.75 | D12: 1219.2 | E12: 550 | F12: SSI-2501 | G12: 46057 | AM12: =E12-H12-I12-J12-K12-L12-M12-N12-O12-P12-Q12-R12-S12-T12-U12-V12-W12-X12-Y12-Z12-AA12-AB12-AC12-AD12-AE12-AF12-AG12-AH12-AI12-AJ12-AK12-AL12 -> 550 | AN12: =B12*C12*D12*AM12/1000000000 -> 1.3519328 | AP12: 650 | AQ12: =AN12*AP12*31.4666 -> 27651.473
A13: 22125 | B13: 12.7 | C13: 158.75 | D13: 1219.2 | E13: 410 | F13: SSI-2501 | G13: 46057 | AM13: =E13-H13-I13-J13-K13-L13-M13-N13-O13-P13-Q13-R13-S13-T13-U13-V13-W13-X13-Y13-Z13-AA13-AB13-AC13-AD13-AE13-AF13-AG13-AH13-AI13-AJ13-AK13-AL13 -> 410 | AN13: =B13*C13*D13*AM13/1000000000 -> 1.0078044 | AP13: 650 | AQ13: =AN13*AP13*31.4666 -> 20612.916
A14: 22126 | B14: 12.7 | C14: 209.55 | D14: 1219.2 | E14: 14 | F14: SSI-2501 | G14: 46057 | AM14: =E14-H14-I14-J14-K14-L14-M14-N14-O14-P14-Q14-R14-S14-T14-U14-V14-W14-X14-Y14-Z14-AA14-AB14-AC14-AD14-AE14-AF14-AG14-AH14-AI14-AJ14-AK14-AL14 -> 14 | AN14: =B14*C14*D14*AM14/1000000000 -> 0.045424941 | AP14: 650 | AQ14: =AN14*AP14*31.4666 -> 929.0895
A15: 22126 | B15: 12.7 | C15: 209.55 | D15: 1219.2 | E15: 445 | F15: SSI-2501 | G15: 46057 | AM15: =E15-H15-I15-J15-K15-L15-M15-N15-O15-P15-Q15-R15-S15-T15-U15-V15-W15-X15-Y15-Z15-AA15-AB15-AC15-AD15-AE15-AF15-AG15-AH15-AI15-AJ15-AK15-AL15 -> 445 | AN15: =B15*C15*D15*AM15/1000000000 -> 1.4438642 | AP15: 650 | AQ15: =AN15*AP15*31.4666 -> 29531.773
A16: 22126 | B16: 12.7 | C16: 209.55 | D16: 1219.2 | E16: 445 | F16: SSI-2501 | G16: 46057 | AM16: =E16-H16-I16-J16-K16-L16-M16-N16-O16-P16-Q16-R16-S16-T16-U16-V16-W16-X16-Y16-Z16-AA16-AB16-AC16-AD16-AE16-AF16-AG16-AH16-AI16-AJ16-AK16-AL16 -> 445 | AN16: =B16*C16*D16*AM16/1000000000 -> 1.4438642 | AP16: 650 | AQ16: =AN16*AP16*31.4666 -> 29531.773
A17: 22126 | B17: 12.7 | C17: 209.55 | D17: 1219.2 | E17: 327 | F17: SSI-2501 | G17: 46057 | AM17: =E17-H17-I17-J17-K17-L17-M17-N17-O17-P17-Q17-R17-S17-T17-U17-V17-W17-X17-Y17-Z17-AA17-AB17-AC17-AD17-AE17-AF17-AG17-AH17-AI17-AJ17-AK17-AL17 -> 327 | AN17: =B17*C17*D17*AM17/1000000000 -> 1.0609968 | AP17: 650 | AQ17: =AN17*AP17*31.4666 -> 21700.876
A18: 22126 | B18: 12.7 | C18: 209.55 | D18: 1219.2 | E18: 327 | F18: SSI-2501 | G18: 46057 | AM18: =E18-H18-I18-J18-K18-L18-M18-N18-O18-P18-Q18-R18-S18-T18-U18-V18-W18-X18-Y18-Z18-AA18-AB18-AC18-AD18-AE18-AF18-AG18-AH18-AI18-AJ18-AK18-AL18 -> 327 | AN18: =B18*C18*D18*AM18/1000000000 -> 1.0609968 | AP18: 650 | AQ18: =AN18*AP18*31.4666 -> 21700.876
A19: 22126 | B19: 12.7 | C19: 209.55 | D19: 1219.2 | E19: 327 | F19: SSI-2501 | G19: 46057 | AM19: =E19-H19-I19-J19-K19-L19-M19-N19-O19-P19-Q19-R19-S19-T19-U19-V19-W19-X19-Y19-Z19-AA19-AB19-AC19-AD19-AE19-AF19-AG19-AH19-AI19-AJ19-AK19-AL19 -> 327 | AN19: =B19*C19*D19*AM19/1000000000 -> 1.0609968 | AP19: 650 | AQ19: =AN19*AP19*31.4666 -> 21700.876
A20: 22126 | B20: 12.7 | C20: 209.55 | D20: 1219.2 | E20: 327 | F20: SSI-2501 | G20: 46057 | AM20: =E20-H20-I20-J20-K20-L20-M20-N20-O20-P20-Q20-R20-S20-T20-U20-V20-W20-X20-Y20-Z20-AA20-AB20-AC20-AD20-AE20-AF20-AG20-AH20-AI20-AJ20-AK20-AL20 -> 327 | AN20: =B20*C20*D20*AM20/1000000000 -> 1.0609968 | AP20: 650 | AQ20: =AN20*AP20*31.4666 -> 21700.876
A21: 22126 | B21: 12.7 | C21: 209.55 | D21: 1219.2 | E21: 166 | F21: SSI-2501 | G21: 46057 | AM21: =E21-H21-I21-J21-K21-L21-M21-N21-O21-P21-Q21-R21-S21-T21-U21-V21-W21-X21-Y21-Z21-AA21-AB21-AC21-AD21-AE21-AF21-AG21-AH21-AI21-AJ21-AK21-AL21 -> 166 | AN21: =B21*C21*D21*AM21/1000000000 -> 0.53861002 | AP21: 650 | AQ21: =AN21*AP21*31.4666 -> 11016.347
A22: 22126 | B22: 12.7 | C22: 209.55 | D22: 1219.2 | E22: 166 | F22: SSI-2501 | G22: 46057 | AM22: =E22-H22-I22-J22-K22-L22-M22-N22-O22-P22-Q22-R22-S22-T22-U22-V22-W22-X22-Y22-Z22-AA22-AB22-AC22-AD22-AE22-AF22-AG22-AH22-AI22-AJ22-AK22-AL22 -> 166 | AN22: =B22*C22*D22*AM22/1000000000 -> 0.53861002 | AP22: 650 | AQ22: =AN22*AP22*31.4666 -> 11016.347
A23: 22126 | B23: 12.7 | C23: 209.55 | D23: 1219.2 | E23: 166 | F23: SSI-2501 | G23: 46057 | AM23: =E23-H23-I23-J23-K23-L23-M23-N23-O23-P23-Q23-R23-S23-T23-U23-V23-W23-X23-Y23-Z23-AA23-AB23-AC23-AD23-AE23-AF23-AG23-AH23-AI23-AJ23-AK23-AL23 -> 166 | AN23: =B23*C23*D23*AM23/1000000000 -> 0.53861002 | AP23: 650 | AQ23: =AN23*AP23*31.4666 -> 11016.347
... A26: 22126 | B26: 12.7 | C26: 209.55 | D26: 1219.2 | E26: 332 | F26: SSI-2502 | G26: 46057 | AM26: =E26-H26-I26-J26-K26-L26-M26-N26-O26-P26-Q26-R26-S26-T26-U26-V26-W26-X26-Y26-Z26-AA26-AB26-AC26-AD26-AE26-AF26-AG26-AH26-AI26-AJ26-AK26-AL26 -> 332 | AN26: =B26*C26*D26*AM26/1000000000 -> 1.07722 | AP26: 650 | AQ26: =AN26*AP26*31.4666 -> 22032.694
A27: 22128 | B27: 12.7 | C27: 1100 | D27: 450.85 | E27: 172 | F27: JTM-2503 | G27: 45846 | W27: 82 | AM27: =E27-H27-I27-J27-K27-L27-M27-N27-O27-P27-Q27-R27-S27-T27-U27-V27-W27-X27-Y27-Z27-AA27-AB27-AC27-AD27-AE27-AF27-AG27-AH27-AI27-AJ27-AK27-AL27 -> 90 | AN27: =B27*C27*D27*AM27/1000000000 -> 0.5668537 | AP27: 630 | AQ27: =AN27*AP27*33.162 -> 11842.742
A28: 22128 | B28: 12.7 | C28: 1100 | D28: 450.85 | E28: 108 | F28: JTM-2503 | G28: 45846 | AM28: =E28-H28-I28-J28-K28-L28-M28-N28-O28-P28-Q28-R28-S28-T28-U28-V28-W28-X28-Y28-Z28-AA28-AB28-AC28-AD28-AE28-AF28-AG28-AH28-AI28-AJ28-AK28-AL28 -> 108 | AN28: =B28*C28*D28*AM28/1000000000 -> 0.68022445 | AP28: 630 | AQ28: =AN28*AP28*33.162 -> 14211.29
A29: 22131 | B29: 12.7 | C29: 209.6 | D29: 450.9 | E29: 500 | F29: TGTM-25003 | G29: 45744 | AM29: =E29-H29-I29-J29-K29-L29-M29-N29-O29-P29-Q29-R29-S29-T29-U29-V29-W29-X29-Y29-Z29-AA29-AB29-AC29-AD29-AE29-AF29-AG29-AH29-AI29-AJ29-AK29-AL29 -> 500 | AN29: =B29*C29*D29*AM29/1000000000 -> 0.60012986 | AO29: 0.876 | AQ29: =AO29*AM29*33.8617 -> 14831.425
A30: 22131 | B30: 12.7 | C30: 209.6 | D30: 450.9 | E30: 500 | F30: TGTM-25003 | G30: 45744 | AM30: =E30-H30-I30-J30-K30-L30-M30-N30-O30-P30-Q30-R30-S30-T30-U30-V30-W30-X30-Y30-Z30-AA30-AB30-AC30-AD30-AE30-AF30-AG30-AH30-AI30-AJ30-AK30-AL30 -> 500 | AN30: =B30*C30*D30*AM30/1000000000 -> 0.60012986 | AO30: 0.876 | AQ30: =AO30*AM30*33.8617 -> 14831.425
A31: 22133 | B31: 12.7 | C31: 108 | D31: 527.1 | E31: 750 | F31: TGTM-25003 | G31: 45744 | AM31: =E31-H31-I31-J31-K31-L31-M31-N31-O31-P31-Q31-R31-S31-T31-U31-V31-W31-X31-Y31-Z31-AA31-AB31-AC31-AD31-AE31-AF31-AG31-AH31-AI31-AJ31-AK31-AL31 -> 750 | AN31: =B31*C31*D31*AM31/1000000000 -> 0.54222777 | AO31: 0.528 | AQ31: =AO31*AM31*33.8617 -> 13409.233
A32: 22134 | B32: 12.7 | C32: 158.8 | D32: 527.1 | E32: 480 | F32: TGTM-25001 | G32: 45706 | AM32: =E32-H32-I32-J32-K32-L32-M32-N32-O32-P32-Q32-R32-S32-T32-U32-V32-W32-X32-Y32-Z32-AA32-AB32-AC32-AD32-AE32-AF32-AG32-AH32-AI32-AJ32-AK32-AL32 -> 480 | AN32: =B32*C32*D32*AM32/1000000000 -> 0.51025641 | AO32: 0.78 | AQ32: =AO32*AM32*34.3391 -> 12856.559
A33: 22135 | B33: 12.7 | C33: 1100 | D33: 527.05 | E33: 78 | F33: JTM-2503 | G33: 45846 | W33: 10 | AM33: =E33-H33-I33-J33-K33-L33-M33-N33-O33-P33-Q33-R33-S33-T33-U33-V33-W33-X33-Y33-Z33-AA33-AB33-AC33-AD33-AE33-AF33-AG33-AH33-AI33-AJ33-AK33-AL33 -> 68 | AN33: =B33*C33*D33*AM33/1000000000 -> 0.50067642 | AP33: 630 | AQ33: =AN33*AP33*33.162 -> 10460.162
A34: 6028573 | B34: 15.9 | C34: 76.2 | D34: 762 | E34: 560 | F34: TGTM-24002 | G34: 45681 | W34: 480 | AM34: =E34-H34-I34-J34-K34-L34-M34-N34-O34-P34-Q34-R34-S34-T34-U34-V34-W34-X34-Y34-Z34-AA34-AB34-AC34-AD34-AE34-AF34-AG34-AH34-AI34-AJ34-AK34-AL34 -> 80 | AN34: =B34*C34*D34*AM34/1000000000 -> 0.073857917 | AO34: 0.69 | AQ34: =AO34*AM34*34.5438 -> 1906.8178
A35: 6028606 | B35: 15.9 | C35: 101.6 | D35: 762 | E35: 400 | F35: TGTM-24002 | G35: 45681 | AM35: =E35-H35-I35-J35-K35-L35-M35-N35-O35-P35-Q35-R35-S35-T35-U35-V35-W35-X35-Y35-Z35-AA35-AB35-AC35-AD35-AE35-AF35-AG35-AH35-AI35-AJ35-AK35-AL35 -> 400 | AN35: =B35*C35*D35*AM35/1000000000 -> 0.49238611 | AO35: 0.92 | AQ35: =AO35*AM35*34.5438 -> 12712.118
A36: 6028606 | B36: 15.9 | C36: 101.6 | D36: 762 | E36: 400 | F36: TGTM-24002 | G36: 45681 | AM36: =E36-H36-I36-J36-K36-L36-M36-N36-O36-P36-Q36-R36-S36-T36-U36-V36-W36-X36-Y36-Z36-AA36-AB36-AC36-AD36-AE36-AF36-AG36-AH36-AI36-AJ36-AK36-AL36 -> 400 | AN36: =B36*C36*D36*AM36/1000000000 -> 0.49238611 | AO36: 0.92 | AQ36: =AO36*AM36*34.5438 -> 12712.118
A37: 6028606 | B37: 15.9 | C37: 101.6 | D37: 762 | E37: 400 | F37: TGTM-24002 | G37: 45681 | AM37: =E37-H37-I37-J37-K37-L37-M37-N37-O37-P37-Q37-R37-S37-T37-U37-V37-W37-X37-Y37-Z37-AA37-AB37-AC37-AD37-AE37-AF37-AG37-AH37-AI37-AJ37-AK37-AL37 -> 400 | AN37: =B37*C37*D37*AM37/1000000000 -> 0.49238611 | AO37: 0.92 | AQ37: =AO37*AM37*34.5438 -> 12712.118
A38: 6028606 | B38: 15.9 | C38: 101.6 | D38: 762 | E38: 400 | F38: TGTM-24002 | G38: 45681 | AM38: =E38-H38-I38-J38-K38-L38-M38-N38-O38-P38-Q38-R38-S38-T38-U38-V38-W38-X38-Y38-Z38-AA38-AB38-AC38-AD38-AE38-AF38-AG38-AH38-AI38-AJ38-AK38-AL38 -> 400 | AN38: =B38*C38*D38*AM38/1000000000 -> 0.49238611 | AO38: 0.92 | AQ38: =AO38*AM38*34.5438 -> 12712.118
A39: 6028622 | B39: 15.9 | C39: 101.6 | D39: 939.8 | E39: 240 | F39: TGTM-24002 | G39: 45681 | AM39: =E39-H39-I39-J39-K39-L39-M39-N39-O39-P39-Q39-R39-S39-T39-U39-V39-W39-X39-Y39-Z39-AA39-AB39-AC39-AD39-AE39-AF39-AG39-AH39-AI39-AJ39-AK39-AL39 -> 240 | AN39: =B39*C39*D39*AM39/1000000000 -> 0.36436572 | AO39: 1.14 | AQ39: =AO39*AM39*34.5438 -> 9451.1837
A40: 6028633 | B40: 15.9 | C40: 177.8 | D40: 939.8 | E40: 104 | F40: JTM-2504 | G40: 45888 | AM40: =E40-H40-I40-J40-K40-L40-M40-N40-O40-P40-Q40-R40-S40-T40-U40-V40-W40-X40-Y40-Z40-AA40-AB40-AC40-AD40-AE40-AF40-AG40-AH40-AI40-AJ40-AK40-AL40 -> 104 | AN40: =B40*C40*D40*AM40/1000000000 -> 0.27631067 | AP40: 735 | AQ40: =AN40*AP40*32.4608 -> 6592.4101
A41: 6028676 | B41: 15.9 | C41: 254 | D41: 762 | E41: 160 | F41: TGTM-24002 | G41: 45681 | AM41: =E41-H41-I41-J41-K41-L41-M41-N41-O41-P41-Q41-R41-S41-T41-U41-V41-W41-X41-Y41-Z41-AA41-AB41-AC41-AD41-AE41-AF41-AG41-AH41-AI41-AJ41-AK41-AL41 -> 160 | AN41: =B41*C41*D41*AM41/1000000000 -> 0.49238611 | AO41: 2.31 | AQ41: =AO41*AM41*34.5438 -> 12767.388
A42: 6028676 | B42: 15.9 | C42: 254 | D42: 762 | E42: 160 | F42: TGTM-24002 | G42: 45681 | AM42: =E42-H42-I42-J42-K42-L42-M42-N42-O42-P42-Q42-R42-S42-T42-U42-V42-W42-X42-Y42-Z42-AA42-AB42-AC42-AD42-AE42-AF42-AG42-AH42-AI42-AJ42-AK42-AL42 -> 160 | AN42: =B42*C42*D42*AM42/1000000000 -> 0.49238611 | AO42: 2.31 | AQ42: =AO42*AM42*34.5438 -> 12767.388
...

Sheet LB-Board
B2: Date In | C2: Item Code. | D2: Decription | E2: Size | H2: BALANCE | J2: F3 ลูกบาศก์ฟุต | K2: Price | L2: PRICE /PCS | M2: Amount | N2: Remark
E3: T(mm) | F3: W | G3: L
C4: RMGROB-FJ-AB-001 | D4: AB 14X1220X2440 | E4: 14 | F4: 1220 | G4: 2440 | H4: 124 | I4: =ROUND(E4*F4*G4*H4/1000000000,2) -> 5.17 | J4: =I4*35.315 -> 182.57855 | K4: 22500 | L4: =E4*F4*G4*K4/1000000000 -> 937.692 | M4: 116273.25 | N4: =H4*L4 -> 116273.81
C5: RMGROB-BJ-AB-002 | D5: AB 14X1220X1550 | E5: 14 | F5: 1220 | G5: 1550 | H5: 20 | I5: =ROUND(E5*F5*G5*H5/1000000000,2) -> 0.53 | J5: =I5*35.315 -> 18.71695 | K5: 23000 | L5: =E5*F5*G5*K5/1000000000 -> 608.902 | M5: 12178 | N5: =H5*L5 -> 12178.04
C6: RMDAXIANG-BJ-AC-003 | D6: AC 16X1220X2440 | E6: 16 | F6: 1220 | G6: 2440 | H6: 265 | I6: =ROUND(E6*F6*G6*H6/1000000000,2) -> 12.62 | J6: =I6*35.315 -> 445.6753 | K6: 19316.03 | L6: =E6*F6*G6*K6/1000000000 -> 919.99933 | M6: 243800 | N6: =H6*L6 -> 243799.82
C7: RMKTM-LB-AB001 | D7: AB 16X11180X1100 | E7: 16 | F7: 1180 | G7: 1100 | H7: 513 | I7: =ROUND(E7*F7*G7*H7/1000000000,2) -> 10.65 | J7: =I7*35.315 -> 376.10475 | K7: 18684.58 | L7: =+M7/H7 -> 388.09846 | M7: 199094.51 | N7: =H7*L7 -> 199094.51
C8: RMKTM-LB-AB002 | D8: AB 16X1180X1000 | E8: 16 | F8: 1180 | G8: 1000 | H8: 219 | I8: =ROUND(E8*F8*G8*H8/1000000000,2) -> 4.13 | J8: =I8*35.315 -> 145.85095 | K8: 18684.58 | L8: =+M8/H8 -> 352.36219 | M8: 77167.32 | N8: =H8*L8 -> 77167.32
C9: RMKTM-LB-AB003 | D9: AB 16X1200X900 | E9: 16 | F9: 1200 | G9: 900 | H9: 40 | I9: =ROUND(E9*F9*G9*H9/1000000000,2) -> 0.69 | J9: =I9*35.315 -> 24.36735 | K9: 18684.58 | L9: =+M9/H9 -> 322.4005 | M9: 12896.02 | N9: =H9*L9 -> 12896.02
B10: TOTAL | H10: =SUM(H4:H9) -> 1181 | I10: =SUM(I4:I9) -> 33.79 | M10: =SUM(M4:M9) -> 661409.1 | N10: =SUM(N4:N9) -> 661409.52
H11: Board | I11: =I10 -> 33.79 | M11: =M10 -> 661409.1 | N11: =M11/I11 -> 19574.108

Sheet MAT-INDO
A1: PART | B1: T | C1: W | D1: L | E1: PCS | F1: INV | G1: IN DATE | H1: OUT DATE - JULY | AM1: BALANCE | AN1: m3 | AO1: USD/m3 | AP1: USD to THB
H2: 1 | I2: 2 | J2: 3 | K2: 4 | L2: 5 | M2: 6 | N2: 7 | O2: 8 | P2: 9 | Q2: 10 | R2: 11 | S2: 12 | T2: 13 | U2: 14 | V2: 15 | W2: 16 | X2: 17 | Y2: 18 | Z2: 19 | AA2: 20 | AB2: 21 | AC2: 22 | AD2: 23 | AE2: 24 | AF2: 25 | AG2: 26 | AH2: 27 | AI2: 28 | AJ2: 29 | AK2: 30 | AL2: 31
A3: 6601608 | B3: 15 | C3: 101.6 | D3: 520.7 | E3: 1100 | F3: INV-13/ASN/TM/II/26 | G3: 46107 | AM3: =E3-H3-I3-J3-K3-L3-M3-N3-O3-P3-Q3-R3-S3-T3-U3-V3-W3-X3-Y3-Z3-AA3-AB3-AC3-AD3-AE3-AF3-AG3-AH3-AI3-AJ3-AK3-AL3 -> 1100 | AN3: =B3*C3*D3*AM3/1000000000 -> 0.87290148 | AO3: 590 | AP3: =AN3*AO3*31.3303 -> 16135.476
A4: 6601608 | B4: 15 | C4: 101.6 | D4: 520.7 | E4: 1500 | F4: INV-13/ASN/TM/II/26 | G4: 46107 | AM4: =E4-H4-I4-J4-K4-L4-M4-N4-O4-P4-Q4-R4-S4-T4-U4-V4-W4-X4-Y4-Z4-AA4-AB4-AC4-AD4-AE4-AF4-AG4-AH4-AI4-AJ4-AK4-AL4 -> 1500 | AN4: =B4*C4*D4*AM4/1000000000 -> 1.1903202 | AO4: 590 | AP4: =AN4*AO4*31.3303 -> 22002.922
A5: 6601608 | B5: 15 | C5: 101.6 | D5: 520.7 | E5: 1500 | F5: INV-13/ASN/TM/II/26 | G5: 46107 | AM5: =E5-H5-I5-J5-K5-L5-M5-N5-O5-P5-Q5-R5-S5-T5-U5-V5-W5-X5-Y5-Z5-AA5-AB5-AC5-AD5-AE5-AF5-AG5-AH5-AI5-AJ5-AK5-AL5 -> 1500 | AN5: =B5*C5*D5*AM5/1000000000 -> 1.1903202 | AO5: 590 | AP5: =AN5*AO5*31.3303 -> 22002.922
A6: 6601609 | B6: 15 | C6: 101.6 | D6: 566.7 | E6: 550 | F6: INV-13/ASN/TM/II/26 | G6: 46107 | I6: 300 | AM6: =E6-H6-I6-J6-K6-L6-M6-N6-O6-P6-Q6-R6-S6-T6-U6-V6-W6-X6-Y6-Z6-AA6-AB6-AC6-AD6-AE6-AF6-AG6-AH6-AI6-AJ6-AK6-AL6 -> 250 | AN6: =B6*C6*D6*AM6/1000000000 -> 0.2159127 | AO6: 590 | AP6: =AN6*AO6*31.3303 -> 3991.1197
A7: 6601613 | B7: 15 | C7: 101.6 | D7: 673.1 | E7: 1000 | F7: INV-13/ASN/TM/II/26 | G7: 46107 | AM7: =E7-H7-I7-J7-K7-L7-M7-N7-O7-P7-Q7-R7-S7-T7-U7-V7-W7-X7-Y7-Z7-AA7-AB7-AC7-AD7-AE7-AF7-AG7-AH7-AI7-AJ7-AK7-AL7 -> 1000 | AN7: =B7*C7*D7*AM7/1000000000 -> 1.0258044 | AO7: 590 | AP7: =AN7*AO7*31.3303 -> 18961.868
A8: 6601625 | B8: 15 | C8: 177.8 | D8: 520.7 | E8: 736 | F8: INV-13/ASN/TM/II/26 | G8: 46107 | AM8: =E8-H8-I8-J8-K8-L8-M8-N8-O8-P8-Q8-R8-S8-T8-U8-V8-W8-X8-Y8-Z8-AA8-AB8-AC8-AD8-AE8-AF8-AG8-AH8-AI8-AJ8-AK8-AL8 -> 736 | AN8: =B8*C8*D8*AM8/1000000000 -> 1.0220883 | AO8: 590 | AP8: =AN8*AO8*31.3303 -> 18893.176
A9: 6601628 | B9: 15 | C9: 177.8 | D9: 673.1 | E9: 300 | F9: INV-13/ASN/TM/II/26 | G9: 46107 | AM9: =E9-H9-I9-J9-K9-L9-M9-N9-O9-P9-Q9-R9-S9-T9-U9-V9-W9-X9-Y9-Z9-AA9-AB9-AC9-AD9-AE9-AF9-AG9-AH9-AI9-AJ9-AK9-AL9 -> 300 | AN9: =B9*C9*D9*AM9/1000000000 -> 0.53854731 | AO9: 590 | AP9: =AN9*AO9*31.3303 -> 9954.9808
A10: 6601632 | B10: 15 | C10: 228.6 | D10: 292.1 | E10: 450 | F10: INV-13/ASN/TM/II/26 | G10: 46107 | AM10: =E10-H10-I10-J10-K10-L10-M10-N10-O10-P10-Q10-R10-S10-T10-U10-V10-W10-X10-Y10-Z10-AA10-AB10-AC10-AD10-AE10-AF10-AG10-AH10-AI10-AJ10-AK10-AL10 -> 450 | AN10: =B10*C10*D10*AM10/1000000000 -> 0.45072491 | AO10: 590 | AP10: =AN10*AO10*31.3303 -> 8331.5944
A11: 6601634 | B11: 15 | C11: 228.6 | D11: 368.3 | E11: 500 | F11: INV-13/ASN/TM/II/26 | G11: 46107 | AM11: =E11-H11-I11-J11-K11-L11-M11-N11-O11-P11-Q11-R11-S11-T11-U11-V11-W11-X11-Y11-Z11-AA11-AB11-AC11-AD11-AE11-AF11-AG11-AH11-AI11-AJ11-AK11-AL11 -> 500 | AN11: =B11*C11*D11*AM11/1000000000 -> 0.63145035 | AO11: 590 | AP11: =AN11*AO11*31.3303 -> 11672.282
A12: 7719403 | B12: 15.9 | C12: 161.9 | D12: 523.8 | E12: 480 | F12: INV-11/ASN/TM/II/26 | G12: 46100 | AJ12: 132 | AM12: =E12-H12-I12-J12-K12-L12-M12-N12-O12-P12-Q12-R12-S12-T12-U12-V12-W12-X12-Y12-Z12-AA12-AB12-AC12-AD12-AE12-AF12-AG12-AH12-AI12-AJ12-AK12-AL12 -> 348 | AN12: =B12*C12*D12*AM12/1000000000 -> 0.46923318 | AO12: 590 | AP12: =AN12*AO12*31.3303 -> 8673.7176
A13: 8156423 | B13: 10.5 | C13: 51 | D13: 550 | E13: 2400 | F13: INV-13/ASN/TM/II/26 | G13: 46107 | AM13: =E13-H13-I13-J13-K13-L13-M13-N13-O13-P13-Q13-R13-S13-T13-U13-V13-W13-X13-Y13-Z13-AA13-AB13-AC13-AD13-AE13-AF13-AG13-AH13-AI13-AJ13-AK13-AL13 -> 2400 | AN13: =B13*C13*D13*AM13/1000000000 -> 0.70686 | AO13: 590 | AP13: =AN13*AO13*31.3303 -> 13066.22
A14: 8156506 | B14: 16 | C14: 86 | D14: 466 | E14: 640 | F14: INV-13/ASN/TM/II/26 | G14: 46107 | AM14: =E14-H14-I14-J14-K14-L14-M14-N14-O14-P14-Q14-R14-S14-T14-U14-V14-W14-X14-Y14-Z14-AA14-AB14-AC14-AD14-AE14-AF14-AG14-AH14-AI14-AJ14-AK14-AL14 -> 640 | AN14: =B14*C14*D14*AM14/1000000000 -> 0.41037824 | AO14: 590 | AP14: =AN14*AO14*31.3303 -> 7585.7913
A15: 8156521 | B15: 16 | C15: 162 | D15: 524 | E15: 336 | F15: INV-13/ASN/TM/II/26 | G15: 46107 | AM15: =E15-H15-I15-J15-K15-L15-M15-N15-O15-P15-Q15-R15-S15-T15-U15-V15-W15-X15-Y15-Z15-AA15-AB15-AC15-AD15-AE15-AF15-AG15-AH15-AI15-AJ15-AK15-AL15 -> 336 | AN15: =B15*C15*D15*AM15/1000000000 -> 0.45635789 | AO15: 590 | AP15: =AN15*AO15*31.3303 -> 8435.7194
A16: 8156565 | B16: 16 | C16: 86 | D16: 474 | E16: 1608 | F16: INV-13/ASN/TM/II/26 | G16: 46107 | AM16: =E16-H16-I16-J16-K16-L16-M16-N16-O16-P16-Q16-R16-S16-T16-U16-V16-W16-X16-Y16-Z16-AA16-AB16-AC16-AD16-AE16-AF16-AG16-AH16-AI16-AJ16-AK16-AL16 -> 1608 | AN16: =B16*C16*D16*AM16/1000000000 -> 1.0487762 | AO16: 590 | AP16: =AN16*AO16*31.3303 -> 19386.499
A17: 8156565 | B17: 16 | C17: 86 | D17: 474 | E17: 952 | F17: INV-13/ASN/TM/II/26 | G17: 46107 | AM17: =E17-H17-I17-J17-K17-L17-M17-N17-O17-P17-Q17-R17-S17-T17-U17-V17-W17-X17-Y17-Z17-AA17-AB17-AC17-AD17-AE17-AF17-AG17-AH17-AI17-AJ17-AK17-AL17 -> 952 | AN17: =B17*C17*D17*AM17/1000000000 -> 0.62091725 | AO17: 590 | AP17: =AN17*AO17*31.3303 -> 11477.579
A18: 8156575 | B18: 16 | C18: 86 | D18: 524 | E18: 296 | F18: INV-13/ASN/TM/II/26 | G18: 46107 | AM18: =E18-H18-I18-J18-K18-L18-M18-N18-O18-P18-Q18-R18-S18-T18-U18-V18-W18-X18-Y18-Z18-AA18-AB18-AC18-AD18-AE18-AF18-AG18-AH18-AI18-AJ18-AK18-AL18 -> 296 | AN18: =B18*C18*D18*AM18/1000000000 -> 0.2134231 | AO18: 590 | AP18: =AN18*AO18*31.3303 -> 3945.0998
A19: 8156575 | B19: 16 | C19: 86 | D19: 524 | E19: 1608 | F19: INV-13/ASN/TM/II/26 | G19: 46107 | AM19: =E19-H19-I19-J19-K19-L19-M19-N19-O19-P19-Q19-R19-S19-T19-U19-V19-W19-X19-Y19-Z19-AA19-AB19-AC19-AD19-AE19-AF19-AG19-AH19-AI19-AJ19-AK19-AL19 -> 1608 | AN19: =B19*C19*D19*AM19/1000000000 -> 1.1594066 | AO19: 590 | AP19: =AN19*AO19*31.3303 -> 21431.488
A20: 8156575 | B20: 16 | C20: 86 | D20: 524 | E20: 1608 | F20: INV-13/ASN/TM/II/26 | G20: 46107 | AM20: =E20-H20-I20-J20-K20-L20-M20-N20-O20-P20-Q20-R20-S20-T20-U20-V20-W20-X20-Y20-Z20-AA20-AB20-AC20-AD20-AE20-AF20-AG20-AH20-AI20-AJ20-AK20-AL20 -> 1608 | AN20: =B20*C20*D20*AM20/1000000000 -> 1.1594066 | AO20: 590 | AP20: =AN20*AO20*31.3303 -> 21431.488
A21: 8156575 | B21: 16 | C21: 86 | D21: 524 | E21: 1608 | F21: INV-13/ASN/TM/II/26 | G21: 46107 | AM21: =E21-H21-I21-J21-K21-L21-M21-N21-O21-P21-Q21-R21-S21-T21-U21-V21-W21-X21-Y21-Z21-AA21-AB21-AC21-AD21-AE21-AF21-AG21-AH21-AI21-AJ21-AK21-AL21 -> 1608 | AN21: =B21*C21*D21*AM21/1000000000 -> 1.1594066 | AO21: 590 | AP21: =AN21*AO21*31.3303 -> 21431.488
A22: 8156578 | B22: 16 | C22: 162 | D22: 491 | E22: 640 | F22: INV-13/ASN/TM/II/26 | G22: 46107 | AM22: =E22-H22-I22-J22-K22-L22-M22-N22-O22-P22-Q22-R22-S22-T22-U22-V22-W22-X22-Y22-Z22-AA22-AB22-AC22-AD22-AE22-AF22-AG22-AH22-AI22-AJ22-AK22-AL22 -> 640 | AN22: =B22*C22*D22*AM22/1000000000 -> 0.81451008 | AO22: 590 | AP22: =AN22*AO22*31.3303 -> 15056.119
A23: 8156585 | B23: 16 | C23: 162 | D23: 568 | E23: 720 | F23: INV-13/ASN/TM/II/26 | G23: 46107 | AM23: =E23-H23-I23-J23-K23-L23-M23-N23-O23-P23-Q23-R23-S23-T23-U23-V23-W23-X23-Y23-Z23-AA23-AB23-AC23-AD23-AE23-AF23-AG23-AH23-AI23-AJ23-AK23-AL23 -> 720 | AN23: =B23*C23*D23*AM23/1000000000 -> 1.0600243 | AO23: 590 | AP23: =AN23*AO23*31.3303 -> 19594.419
A24: 8156588 | B24: 12 | C24: 89 | D24: 864 | E24: 320 | F24: INV-13/ASN/TM/II/26 | G24: 46107 | AM24: =E24-H24-I24-J24-K24-L24-M24-N24-O24-P24-Q24-R24-S24-T24-U24-V24-W24-X24-Y24-Z24-AA24-AB24-AC24-AD24-AE24-AF24-AG24-AH24-AI24-AJ24-AK24-AL24 -> 320 | AN24: =B24*C24*D24*AM24/1000000000 -> 0.29528064 | AO24: 590 | AP24: =AN24*AO24*31.3303 -> 5458.2263
... A35: 8843617 | B35: 15 | C35: 229 | D35: 215.9 | E35: 588 | F35: INV-13/ASN/TM/II/26 | G35: 46107 | AM35: =E35-H35-I35-J35-K35-L35-M35-N35-O35-P35-Q35-R35-S35-T35-U35-V35-W35-X35-Y35-Z35-AA35-AB35-AC35-AD35-AE35-AF35-AG35-AH35-AI35-AJ35-AK35-AL35 -> 588 | AN35: =B35*C35*D35*AM35/1000000000 -> 0.4360705 | AO35: 590 | AP35: =AN35*AO35*31.3303 -> 8060.7096
A36: RUBBER S4S | B36: 15 | C36: 101.6 | D36: 520.7 | E36: 1500 | F36: INV-14/ASN/TM/VI/26 | G36: 46220 | AM36: =E36-H36-I36-J36-K36-L36-M36-N36-O36-P36-Q36-R36-S36-T36-U36-V36-W36-X36-Y36-Z36-AA36-AB36-AC36-AD36-AE36-AF36-AG36-AH36-AI36-AJ36-AK36-AL36 -> 1500 | AN36: =B36*C36*D36*AM36/1000000000 -> 1.1903202 | AO36: 590 | AP36: =AN36*AO36*32.8679 -> 23082.762
A37: RUBBER S4S | B37: 15 | C37: 101.6 | D37: 520.7 | E37: 1500 | F37: INV-14/ASN/TM/VI/26 | G37: 46220 | AM37: =E37-H37-I37-J37-K37-L37-M37-N37-O37-P37-Q37-R37-S37-T37-U37-V37-W37-X37-Y37-Z37-AA37-AB37-AC37-AD37-AE37-AF37-AG37-AH37-AI37-AJ37-AK37-AL37 -> 1500 | AN37: =B37*C37*D37*AM37/1000000000 -> 1.1903202 | AO37: 590 | AP37: =AN37*AO37*32.8679 -> 23082.762
A38: RUBBER S4S | B38: 15 | C38: 101.6 | D38: 520.7 | E38: 1500 | F38: INV-14/ASN/TM/VI/26 | G38: 46220 | AM38: =E38-H38-I38-J38-K38-L38-M38-N38-O38-P38-Q38-R38-S38-T38-U38-V38-W38-X38-Y38-Z38-AA38-AB38-AC38-AD38-AE38-AF38-AG38-AH38-AI38-AJ38-AK38-AL38 -> 1500 | AN38: =B38*C38*D38*AM38/1000000000 -> 1.1903202 | AO38: 590 | AP38: =AN38*AO38*32.8679 -> 23082.762
A39: RUBBER S4S | B39: 15 | C39: 101.6 | D39: 520.7 | E39: 1500 | F39: INV-14/ASN/TM/VI/26 | G39: 46220 | AM39: =E39-H39-I39-J39-K39-L39-M39-N39-O39-P39-Q39-R39-S39-T39-U39-V39-W39-X39-Y39-Z39-AA39-AB39-AC39-AD39-AE39-AF39-AG39-AH39-AI39-AJ39-AK39-AL39 -> 1500 | AN39: =B39*C39*D39*AM39/1000000000 -> 1.1903202 | AO39: 590 | AP39: =AN39*AO39*32.8679 -> 23082.762
A40: RUBBER S4S | B40: 15 | C40: 101.6 | D40: 520.7 | E40: 1500 | F40: INV-14/ASN/TM/VI/26 | G40: 46220 | AM40: =E40-H40-I40-J40-K40-L40-M40-N40-O40-P40-Q40-R40-S40-T40-U40-V40-W40-X40-Y40-Z40-AA40-AB40-AC40-AD40-AE40-AF40-AG40-AH40-AI40-AJ40-AK40-AL40 -> 1500 | AN40: =B40*C40*D40*AM40/1000000000 -> 1.1903202 | AO40: 590 | AP40: =AN40*AO40*32.8679 -> 23082.762
A41: RUBBER S4S | B41: 15 | C41: 101.6 | D41: 520.7 | E41: 1500 | F41: INV-14/ASN/TM/VI/26 | G41: 46220 | AM41: =E41-H41-I41-J41-K41-L41-M41-N41-O41-P41-Q41-R41-S41-T41-U41-V41-W41-X41-Y41-Z41-AA41-AB41-AC41-AD41-AE41-AF41-AG41-AH41-AI41-AJ41-AK41-AL41 -> 1500 | AN41: =B41*C41*D41*AM41/1000000000 -> 1.1903202 | AO41: 590 | AP41: =AN41*AO41*32.8679 -> 23082.762
A42: RUBBER S4S | B42: 15 | C42: 101.6 | D42: 566.7 | E42: 570 | F42: INV-14/ASN/TM/VI/26 | G42: 46220 | AM42: =E42-H42-I42-J42-K42-L42-M42-N42-O42-P42-Q42-R42-S42-T42-U42-V42-W42-X42-Y42-Z42-AA42-AB42-AC42-AD42-AE42-AF42-AG42-AH42-AI42-AJ42-AK42-AL42 -> 570 | AN42: =B42*C42*D42*AM42/1000000000 -> 0.49228096 | AO42: 590 | AP42: =AN42*AO42*32.8679 -> 9546.3423
A43: RUBBER S4S | B43: 15 | C43: 101.6 | D43: 520.7 | E43: 1022 | F43: INV-14/ASN/TM/VI/26 | G43: 46220 | AM43: =E43-H43-I43-J43-K43-L43-M43-N43-O43-P43-Q43-R43-S43-T43-U43-V43-W43-X43-Y43-Z43-AA43-AB43-AC43-AD43-AE43-AF43-AG43-AH43-AI43-AJ43-AK43-AL43 -> 1022 | AN43: =B43*C43*D43*AM43/1000000000 -> 0.81100483 | AO43: 590 | AP43: =AN43*AO43*32.8679 -> 15727.055
A44: RUBBER S4S | B44: 15 | C44: 101.6 | D44: 495.3 | E44: 951 | F44: INV-14/ASN/TM/VI/26 | G44: 46220 | AM44: =E44-H44-I44-J44-K44-L44-M44-N44-O44-P44-Q44-R44-S44-T44-U44-V44-W44-X44-Y44-Z44-AA44-AB44-AC44-AD44-AE44-AF44-AG44-AH44-AI44-AJ44-AK44-AL44 -> 951 | AN44: =B44*C44*D44*AM44/1000000000 -> 0.71785018 | AO44: 590 | AP44: =AN44*AO44*32.8679 -> 13920.594
A45: RUBBER S4S | B45: 15 | C45: 101.6 | D45: 444.5 | E45: 959 | F45: INV-14/ASN/TM/VI/26 | G45: 46220 | AM45: =E45-H45-I45-J45-K45-L45-M45-N45-O45-P45-Q45-R45-S45-T45-U45-V45-W45-X45-Y45-Z45-AA45-AB45-AC45-AD45-AE45-AF45-AG45-AH45-AI45-AJ45-AK45-AL45 -> 959 | AN45: =B45*C45*D45*AM45/1000000000 -> 0.64964386 | AO45: 590 | AP45: =AN45*AO45*32.8679 -> 12597.933
A46: RUBBER S4S | B46: 17 | C46: 83 | D46: 520 | E46: 1560 | F46: INV-14/ASN/TM/VI/26 | G46: 46220 | AM46: =E46-H46-I46-J46-K46-L46-M46-N46-O46-P46-Q46-R46-S46-T46-U46-V46-W46-X46-Y46-Z46-AA46-AB46-AC46-AD46-AE46-AF46-AG46-AH46-AI46-AJ46-AK46-AL46 -> 1560 | AN46: =B46*C46*D46*AM46/1000000000 -> 1.1446032 | AO46: 530 | AP46: =AN46*AO46*32.8679 -> 19938.973
A47: RUBBER S4S | B47: 17 | C47: 83 | D47: 520 | E47: 1560 | F47: INV-14/ASN/TM/VI/26 | G47: 46220 | AM47: =E47-H47-I47-J47-K47-L47-M47-N47-O47-P47-Q47-R47-S47-T47-U47-V47-W47-X47-Y47-Z47-AA47-AB47-AC47-AD47-AE47-AF47-AG47-AH47-AI47-AJ47-AK47-AL47 -> 1560 | AN47: =B47*C47*D47*AM47/1000000000 -> 1.1446032 | AO47: 530 | AP47: =AN47*AO47*32.8679 -> 19938.973
... A49: RUBBER S4S | B49: 17 | C49: 73 | D49: 520 | E49: 1740 | F49: INV-14/ASN/TM/VI/26 | G49: 46220 | AM49: =E49-H49-I49-J49-K49-L49-M49-N49-O49-P49-Q49-R49-S49-T49-U49-V49-W49-X49-Y49-Z49-AA49-AB49-AC49-AD49-AE49-AF49-AG49-AH49-AI49-AJ49-AK49-AL49 -> 1740 | AN49: =B49*C49*D49*AM49/1000000000 -> 1.1228568 | AO49: 530 | AP49: =AN49*AO49*32.8679 -> 19560.151
AN51: =SUM(AN3:AN49) -> 37.991358 | AP51: =SUM(AP3:AP49) -> 706326.91 | AQ51: =AP51/AN51 -> 18591.778

Sheet TAIWAN
A1: TYPE | B1: T | C1: W | D1: L | E1: PCS | F1: INV | G1: IN DATE | H1: OUT DATE - JULY | AM1: BALANCE | AN1: m3 | AO1: USD/PCS | AP1: USD/m3 | AQ1: USD to THB
H2: 1 | I2: 2 | J2: 3 | K2: 4 | L2: 5 | M2: 6 | N2: 7 | O2: 8 | P2: 9 | Q2: 10 | R2: 11 | S2: 12 | T2: 13 | U2: 14 | V2: 15 | W2: 16 | X2: 17 | Y2: 18 | Z2: 19 | AA2: 20 | AB2: 21 | AC2: 22 | AD2: 23 | AE2: 24 | AF2: 25 | AG2: 26 | AH2: 27 | AI2: 28 | AJ2: 29 | AK2: 30 | AL2: 31
A3: BIRCH WOOD | B3: 25.8 | C3: 420 | D3: 500 | E3: 168 | G3: 45772 | AM3: =E3-H3-I3-J3-K3-L3-M3-N3-O3-P3-Q3-R3-S3-T3-U3-V3-W3-X3-Y3-Z3-AA3-AB3-AC3-AD3-AE3-AF3-AG3-AH3-AI3-AJ3-AK3-AL3 -> 168 | AN3: =B3*C3*D3*AM3/1000000000 -> 0.910224 | AO3: 0.56 | AQ3: =AM3*AO3*33.8783 -> 3187.2705
A4: BIRCH WOOD | B4: 20 | C4: 97 | D4: 890 | E4: 500 | G4: 45772 | AM4: =E4-H4-I4-J4-K4-L4-M4-N4-O4-P4-Q4-R4-S4-T4-U4-V4-W4-X4-Y4-Z4-AA4-AB4-AC4-AD4-AE4-AF4-AG4-AH4-AI4-AJ4-AK4-AL4 -> 500 | AN4: =B4*C4*D4*AM4/1000000000 -> 0.8633 | AO4: 0.42 | AQ4: =AM4*AO4*33.8783 -> 7114.443
A5: BIRCH WOOD | B5: 12.3 | C5: 79 | D5: 510 | E5: 1640 | G5: 45772 | AM5: =E5-H5-I5-J5-K5-L5-M5-N5-O5-P5-Q5-R5-S5-T5-U5-V5-W5-X5-Y5-Z5-AA5-AB5-AC5-AD5-AE5-AF5-AG5-AH5-AI5-AJ5-AK5-AL5 -> 1640 | AN5: =B5*C5*D5*AM5/1000000000 -> 0.81272988 | AO5: 0.31 | AQ5: =AM5*AO5*33.8783 -> 17223.728
A6: BIRCH WOOD | B6: 20 | C6: 97 | D6: 890 | E6: 500 | G6: 45772 | AM6: =E6-H6-I6-J6-K6-L6-M6-N6-O6-P6-Q6-R6-S6-T6-U6-V6-W6-X6-Y6-Z6-AA6-AB6-AC6-AD6-AE6-AF6-AG6-AH6-AI6-AJ6-AK6-AL6 -> 500 | AN6: =B6*C6*D6*AM6/1000000000 -> 0.8633 | AO6: 0.35 | AQ6: =AM6*AO6*33.8783 -> 5928.7025
A7: BIRCH WOOD | B7: 12.3 | C7: 41.3 | D7: 700 | E7: 540 | G7: 45772 | AM7: =E7-H7-I7-J7-K7-L7-M7-N7-O7-P7-Q7-R7-S7-T7-U7-V7-W7-X7-Y7-Z7-AA7-AB7-AC7-AD7-AE7-AF7-AG7-AH7-AI7-AJ7-AK7-AL7 -> 540 | AN7: =B7*C7*D7*AM7/1000000000 -> 0.19202022 | AO7: 0.32 | AQ7: =AM7*AO7*33.8783 -> 5854.1702
A8: BIRCH WOOD | B8: 20 | C8: 52 | D8: 690 | E8: 709 | G8: 45772 | W8: 171 | Z8: 80 | AA8: 136 | AC8: 210 | AM8: =E8-H8-I8-J8-K8-L8-M8-N8-O8-P8-Q8-R8-S8-T8-U8-V8-W8-X8-Y8-Z8-AA8-AB8-AC8-AD8-AE8-AF8-AG8-AH8-AI8-AJ8-AK8-AL8 -> 112 | AN8: =B8*C8*D8*AM8/1000000000 -> 0.0803712 | AO8: 0.29 | AQ8: =AM8*AO8*33.8783 -> 1100.3672
A9: BIRCH WOOD | B9: 25.8 | C9: 420 | D9: 500 | E9: 164 | G9: 45772 | AM9: =E9-H9-I9-J9-K9-L9-M9-N9-O9-P9-Q9-R9-S9-T9-U9-V9-W9-X9-Y9-Z9-AA9-AB9-AC9-AD9-AE9-AF9-AG9-AH9-AI9-AJ9-AK9-AL9 -> 164 | AN9: =B9*C9*D9*AM9/1000000000 -> 0.888552 | AO9: 0.87 | AQ9: =AM9*AO9*33.8783 -> 4833.7558
A10: BIRCH WOOD | B10: 12.2 | C10: 41.3 | D10: 850 | E10: 1500 | G10: 45772 | O10: 1317 | AM10: =E10-H10-I10-J10-K10-L10-M10-N10-O10-P10-Q10-R10-S10-T10-U10-V10-W10-X10-Y10-Z10-AA10-AB10-AC10-AD10-AE10-AF10-AG10-AH10-AI10-AJ10-AK10-AL10 -> 183 | AN10: =B10*C10*D10*AM10/1000000000 -> 0.078375423 | AO10: 0.25 | AQ10: =AM10*AO10*33.8783 -> 1549.9322
A11: BIRCH WOOD | B11: 20 | C11: 97 | D11: 850 | E11: 500 | G11: 45772 | W11: 256 | AM11: =E11-H11-I11-J11-K11-L11-M11-N11-O11-P11-Q11-R11-S11-T11-U11-V11-W11-X11-Y11-Z11-AA11-AB11-AC11-AD11-AE11-AF11-AG11-AH11-AI11-AJ11-AK11-AL11 -> 244 | AN11: =B11*C11*D11*AM11/1000000000 -> 0.402356 | AO11: 0.45 | AQ11: =AM11*AO11*33.8783 -> 3719.8373
A12: BIRCH WOOD | B12: 20 | C12: 97 | D12: 510 | E12: 594 | G12: 45772 | AM12: =E12-H12-I12-J12-K12-L12-M12-N12-O12-P12-Q12-R12-S12-T12-U12-V12-W12-X12-Y12-Z12-AA12-AB12-AC12-AD12-AE12-AF12-AG12-AH12-AI12-AJ12-AK12-AL12 -> 594 | AN12: =B12*C12*D12*AM12/1000000000 -> 0.5877036 | AO12: 0.89 | AQ12: =AM12*AO12*33.8783 -> 17910.102
A13: BIRCH WOOD | B13: 12.2 | C13: 31.75 | D13: 430 | E13: 4500 | G13: 45772 | AE13: 791 | AM13: =E13-H13-I13-J13-K13-L13-M13-N13-O13-P13-Q13-R13-S13-T13-U13-V13-W13-X13-Y13-Z13-AA13-AB13-AC13-AD13-AE13-AF13-AG13-AH13-AI13-AJ13-AK13-AL13 -> 3709 | AN13: =B13*C13*D13*AM13/1000000000 -> 0.61777289 | AO13: 0.19 | AQ13: =AM13*AO13*33.8783 -> 23874.377
A14: BIRCH WOOD | B14: 20 | C14: 97 | D14: 510 | E14: 606 | G14: 45772 | AM14: =E14-H14-I14-J14-K14-L14-M14-N14-O14-P14-Q14-R14-S14-T14-U14-V14-W14-X14-Y14-Z14-AA14-AB14-AC14-AD14-AE14-AF14-AG14-AH14-AI14-AJ14-AK14-AL14 -> 606 | AN14: =B14*C14*D14*AM14/1000000000 -> 0.5995764 | AO14: 0.89 | AQ14: =AM14*AO14*33.8783 -> 18271.922
A15: BIRCH WOOD | B15: 20 | C15: 97 | D15: 510 | E15: 800 | G15: 45772 | AM15: =E15-H15-I15-J15-K15-L15-M15-N15-O15-P15-Q15-R15-S15-T15-U15-V15-W15-X15-Y15-Z15-AA15-AB15-AC15-AD15-AE15-AF15-AG15-AH15-AI15-AJ15-AK15-AL15 -> 800 | AN15: =B15*C15*D15*AM15/1000000000 -> 0.79152 | AO15: 0.89 | AQ15: =AM15*AO15*33.8783 -> 24121.35
A16: BIRCH WOOD | B16: 20 | C16: 97 | D16: 510 | E16: 500 | G16: 45772 | AM16: =E16-H16-I16-J16-K16-L16-M16-N16-O16-P16-Q16-R16-S16-T16-U16-V16-W16-X16-Y16-Z16-AA16-AB16-AC16-AD16-AE16-AF16-AG16-AH16-AI16-AJ16-AK16-AL16 -> 500 | AN16: =B16*C16*D16*AM16/1000000000 -> 0.4947 | AO16: 0.89 | AQ16: =AM16*AO16*33.8783 -> 15075.844
A17: BIRCH WOOD | B17: 20 | C17: 97 | D17: 510 | E17: 800 | G17: 45772 | AM17: =E17-H17-I17-J17-K17-L17-M17-N17-O17-P17-Q17-R17-S17-T17-U17-V17-W17-X17-Y17-Z17-AA17-AB17-AC17-AD17-AE17-AF17-AG17-AH17-AI17-AJ17-AK17-AL17 -> 800 | AN17: =B17*C17*D17*AM17/1000000000 -> 0.79152 | AO17: 0.89 | AQ17: =AM17*AO17*33.8783 -> 24121.35
A18: BIRCH WOOD | B18: 20 | C18: 97 | D18: 550 | E18: 800 | G18: 45772 | AK18: 283 | AM18: =E18-H18-I18-J18-K18-L18-M18-N18-O18-P18-Q18-R18-S18-T18-U18-V18-W18-X18-Y18-Z18-AA18-AB18-AC18-AD18-AE18-AF18-AG18-AH18-AI18-AJ18-AK18-AL18 -> 517 | AN18: =B18*C18*D18*AM18/1000000000 -> 0.551639 | AO18: 0.41 | AQ18: =AM18*AO18*33.8783 -> 7181.1833
A19: BIRCH WOOD | B19: 20 | C19: 97 | D19: 510 | E19: 800 | G19: 45772 | AM19: =E19-H19-I19-J19-K19-L19-M19-N19-O19-P19-Q19-R19-S19-T19-U19-V19-W19-X19-Y19-Z19-AA19-AB19-AC19-AD19-AE19-AF19-AG19-AH19-AI19-AJ19-AK19-AL19 -> 800 | AN19: =B19*C19*D19*AM19/1000000000 -> 0.79152 | AO19: 0.89 | AQ19: =AM19*AO19*33.8783 -> 24121.35
A20: BIRCH WOOD | B20: 20 | C20: 97 | D20: 510 | E20: 800 | G20: 45772 | W20: 376 | AA20: 318 | AM20: =E20-H20-I20-J20-K20-L20-M20-N20-O20-P20-Q20-R20-S20-T20-U20-V20-W20-X20-Y20-Z20-AA20-AB20-AC20-AD20-AE20-AF20-AG20-AH20-AI20-AJ20-AK20-AL20 -> 106 | AN20: =B20*C20*D20*AM20/1000000000 -> 0.1048764 | AO20: 0.89 | AQ20: =AM20*AO20*33.8783 -> 3196.0788
A21: BIRCH WOOD | B21: 20 | C21: 97 | D21: 550 | E21: 800 | G21: 45772 | AM21: =E21-H21-I21-J21-K21-L21-M21-N21-O21-P21-Q21-R21-S21-T21-U21-V21-W21-X21-Y21-Z21-AA21-AB21-AC21-AD21-AE21-AF21-AG21-AH21-AI21-AJ21-AK21-AL21 -> 800 | AN21: =B21*C21*D21*AM21/1000000000 -> 0.8536 | AO21: 0.41 | AQ21: =AM21*AO21*33.8783 -> 11112.082
A22: BIRCH WOOD | B22: 20 | C22: 52 | D22: 690 | E22: 630 | G22: 45772 | K22: 162 | AM22: =E22-H22-I22-J22-K22-L22-M22-N22-O22-P22-Q22-R22-S22-T22-U22-V22-W22-X22-Y22-Z22-AA22-AB22-AC22-AD22-AE22-AF22-AG22-AH22-AI22-AJ22-AK22-AL22 -> 468 | AN22: =B22*C22*D22*AM22/1000000000 -> 0.3358368 | AO22: 0.29 | AQ22: =AM22*AO22*33.8783 -> 4597.9629
A23: BIRCH WOOD | B23: 20 | C23: 97 | D23: 510 | E23: 430 | G23: 45772 | AM23: =E23-H23-I23-J23-K23-L23-M23-N23-O23-P23-Q23-R23-S23-T23-U23-V23-W23-X23-Y23-Z23-AA23-AB23-AC23-AD23-AE23-AF23-AG23-AH23-AI23-AJ23-AK23-AL23 -> 430 | AN23: =B23*C23*D23*AM23/1000000000 -> 0.425442 | AO23: 0.89 | AQ23: =AM23*AO23*33.8783 -> 12965.225
A24: BIRCH WOOD | B24: 14 | C24: 45 | D24: 550 | E24: 1226 | G24: 45772 | AM24: =E24-H24-I24-J24-K24-L24-M24-N24-O24-P24-Q24-R24-S24-T24-U24-V24-W24-X24-Y24-Z24-AA24-AB24-AC24-AD24-AE24-AF24-AG24-AH24-AI24-AJ24-AK24-AL24 -> 1226 | AN24: =B24*C24*D24*AM24/1000000000 -> 0.424809 | AO24: 0.33 | AQ24: =AM24*AO24*33.8783 -> 13706.483
A25: BIRCH WOOD | B25: 18 | C25: 257 | D25: 470 | E25: 400 | G25: 45772 | AM25: =E25-H25-I25-J25-K25-L25-M25-N25-O25-P25-Q25-R25-S25-T25-U25-V25-W25-X25-Y25-Z25-AA25-AB25-AC25-AD25-AE25-AF25-AG25-AH25-AI25-AJ25-AK25-AL25 -> 400 | AN25: =B25*C25*D25*AM25/1000000000 -> 0.869688 | AO25: 0.35 | AQ25: =AM25*AO25*33.8783 -> 4742.962
A26: BIRCH WOOD | B26: 21 | C26: 69 | D26: 550 | E26: 600 | G26: 45772 | W26: 400 | AM26: =E26-H26-I26-J26-K26-L26-M26-N26-O26-P26-Q26-R26-S26-T26-U26-V26-W26-X26-Y26-Z26-AA26-AB26-AC26-AD26-AE26-AF26-AG26-AH26-AI26-AJ26-AK26-AL26 -> 200 | AN26: =B26*C26*D26*AM26/1000000000 -> 0.15939 | AO26: 0.34 | AQ26: =AM26*AO26*33.8783 -> 2303.7244
A27: BIRCH WOOD | B27: 21 | C27: 62 | D27: 660 | E27: 350 | G27: 45772 | AM27: =E27-H27-I27-J27-K27-L27-M27-N27-O27-P27-Q27-R27-S27-T27-U27-V27-W27-X27-Y27-Z27-AA27-AB27-AC27-AD27-AE27-AF27-AG27-AH27-AI27-AJ27-AK27-AL27 -> 350 | AN27: =B27*C27*D27*AM27/1000000000 -> 0.300762 | AO27: 0.7 | AQ27: =AM27*AO27*33.8783 -> 8300.1835
A28: BIRCH WOOD | B28: 22 | C28: 100 | D28: 900 | E28: 170 | G28: 45772 | AM28: =E28-H28-I28-J28-K28-L28-M28-N28-O28-P28-Q28-R28-S28-T28-U28-V28-W28-X28-Y28-Z28-AA28-AB28-AC28-AD28-AE28-AF28-AG28-AH28-AI28-AJ28-AK28-AL28 -> 170 | AN28: =B28*C28*D28*AM28/1000000000 -> 0.3366 | AO28: 0.78 | AQ28: =AM28*AO28*33.8783 -> 4492.2626
A29: BIRCH WOOD | B29: 20 | C29: 97 | D29: 510 | E29: 800 | G29: 45772 | AM29: =E29-H29-I29-J29-K29-L29-M29-N29-O29-P29-Q29-R29-S29-T29-U29-V29-W29-X29-Y29-Z29-AA29-AB29-AC29-AD29-AE29-AF29-AG29-AH29-AI29-AJ29-AK29-AL29 -> 800 | AN29: =B29*C29*D29*AM29/1000000000 -> 0.79152 | AO29: 0.89 | AQ29: =AM29*AO29*33.8783 -> 24121.35
A30: BIRCH WOOD | B30: 20 | C30: 52 | D30: 830 | E30: 800 | G30: 45772 | AM30: =E30-H30-I30-J30-K30-L30-M30-N30-O30-P30-Q30-R30-S30-T30-U30-V30-W30-X30-Y30-Z30-AA30-AB30-AC30-AD30-AE30-AF30-AG30-AH30-AI30-AJ30-AK30-AL30 -> 800 | AN30: =B30*C30*D30*AM30/1000000000 -> 0.69056 | AO30: 0.26 | AQ30: =AM30*AO30*33.8783 -> 7046.6864
A31: BIRCH WOOD | B31: 20 | C31: 97 | D31: 890 | E31: 550 | G31: 45772 | AM31: =E31-H31-I31-J31-K31-L31-M31-N31-O31-P31-Q31-R31-S31-T31-U31-V31-W31-X31-Y31-Z31-AA31-AB31-AC31-AD31-AE31-AF31-AG31-AH31-AI31-AJ31-AK31-AL31 -> 550 | AN31: =B31*C31*D31*AM31/1000000000 -> 0.94963 | AO31: 0.45 | AQ31: =AM31*AO31*33.8783 -> 8384.8792
A32: BIRCH WOOD | B32: 20 | C32: 97 | D32: 510 | E32: 700 | G32: 45772 | AM32: =E32-H32-I32-J32-K32-L32-M32-N32-O32-P32-Q32-R32-S32-T32-U32-V32-W32-X32-Y32-Z32-AA32-AB32-AC32-AD32-AE32-AF32-AG32-AH32-AI32-AJ32-AK32-AL32 -> 700 | AN32: =B32*C32*D32*AM32/1000000000 -> 0.69258 | AO32: 0.89 | AQ32: =AM32*AO32*33.8783 -> 21106.181
A33: BIRCH WOOD | B33: 20 | C33: 97 | D33: 550 | E33: 800 | G33: 45772 | AM33: =E33-H33-I33-J33-K33-L33-M33-N33-O33-P33-Q33-R33-S33-T33-U33-V33-W33-X33-Y33-Z33-AA33-AB33-AC33-AD33-AE33-AF33-AG33-AH33-AI33-AJ33-AK33-AL33 -> 800 | AN33: =B33*C33*D33*AM33/1000000000 -> 0.8536 | AO33: 0.41 | AQ33: =AM33*AO33*33.8783 -> 11112.082
A34: BIRCH WOOD | B34: 20 | C34: 97 | D34: 510 | E34: 300 | G34: 45772 | AM34: =E34-H34-I34-J34-K34-L34-M34-N34-O34-P34-Q34-R34-S34-T34-U34-V34-W34-X34-Y34-Z34-AA34-AB34-AC34-AD34-AE34-AF34-AG34-AH34-AI34-AJ34-AK34-AL34 -> 300 | AN34: =B34*C34*D34*AM34/1000000000 -> 0.29682 | AO34: 0.89 | AQ34: =AM34*AO34*33.8783 -> 9045.5061
A35: BIRCH WOOD | B35: 9.53 | C35: 63.5 | D35: 510 | E35: 1300 | G35: 45772 | AM35: =E35-H35-I35-J35-K35-L35-M35-N35-O35-P35-Q35-R35-S35-T35-U35-V35-W35-X35-Y35-Z35-AA35-AB35-AC35-AD35-AE35-AF35-AG35-AH35-AI35-AJ35-AK35-AL35 -> 1300 | AN35: =B35*C35*D35*AM35/1000000000 -> 0.40121777 | AO35: 0.27 | AQ35: =AM35*AO35*33.8783 -> 11891.283
A36: BIRCH WOOD | B36: 20 | C36: 97 | D36: 510 | E36: 600 | G36: 45772 | AM36: =E36-H36-I36-J36-K36-L36-M36-N36-O36-P36-Q36-R36-S36-T36-U36-V36-W36-X36-Y36-Z36-AA36-AB36-AC36-AD36-AE36-AF36-AG36-AH36-AI36-AJ36-AK36-AL36 -> 600 | AN36: =B36*C36*D36*AM36/1000000000 -> 0.59364 | AO36: 0.89 | AQ36: =AM36*AO36*33.8783 -> 18091.012
A37: BIRCH WOOD | B37: 25.8 | C37: 420 | D37: 500 | E37: 168 | G37: 45772 | AM37: =E37-H37-I37-J37-K37-L37-M37-N37-O37-P37-Q37-R37-S37-T37-U37-V37-W37-X37-Y37-Z37-AA37-AB37-AC37-AD37-AE37-AF37-AG37-AH37-AI37-AJ37-AK37-AL37 -> 168 | AN37: =B37*C37*D37*AM37/1000000000 -> 0.910224 | AO37: 0.56 | AQ37: =AM37*AO37*33.8783 -> 3187.2705
A38: BIRCH WOOD | B38: 20 | C38: 97 | D38: 510 | E38: 700 | G38: 45772 | AM38: =E38-H38-I38-J38-K38-L38-M38-N38-O38-P38-Q38-R38-S38-T38-U38-V38-W38-X38-Y38-Z38-AA38-AB38-AC38-AD38-AE38-AF38-AG38-AH38-AI38-AJ38-AK38-AL38 -> 700 | AN38: =B38*C38*D38*AM38/1000000000 -> 0.69258 | AO38: 0.89 | AQ38: =AM38*AO38*33.8783 -> 21106.181
... A41: BIRCH WOOD | B41: 9.53 | C41: 63.5 | D41: 510 | E41: 1900 | G41: 45772 | AM41: =E41-H41-I41-J41-K41-L41-M41-N41-O41-P41-Q41-R41-S41-T41-U41-V41-W41-X41-Y41-Z41-AA41-AB41-AC41-AD41-AE41-AF41-AG41-AH41-AI41-AJ41-AK41-AL41 -> 1900 | AN41: =B41*C41*D41*AM41/1000000000 -> 0.5863952 | AO41: 0.27 | AQ41: =AM41*AO41*33.8783 -> 17379.568
A42: BIRCH WOOD | B42: 9.53 | C42: 63.5 | D42: 550 | E42: 2400 | G42: 45772 | Y42: 1102 | Z42: 998 | AM42: =E42-H42-I42-J42-K42-L42-M42-N42-O42-P42-Q42-R42-S42-T42-U42-V42-W42-X42-Y42-Z42-AA42-AB42-AC42-AD42-AE42-AF42-AG42-AH42-AI42-AJ42-AK42-AL42 -> 300 | AN42: =B42*C42*D42*AM42/1000000000 -> 0.099850575 | AO42: 0.25 | AQ42: =AM42*AO42*33.8783 -> 2540.8725
...

Sheet TAIWAN (Rev)
A1: TYPE | B1: T | C1: W | D1: L | E1: PCS | F1: IN DATE | G1: OUT DATE - JULY | AL1: BALANCE | AM1: m3 | AN1: USD/PCS | AO1: USD/m3 | AP1: USD to THB
G2: 1 | H2: 2 | I2: 3 | J2: 4 | K2: 5 | L2: 6 | M2: 7 | N2: 8 | O2: 9 | P2: 10 | Q2: 11 | R2: 12 | S2: 13 | T2: 14 | U2: 15 | V2: 16 | W2: 17 | X2: 18 | Y2: 19 | Z2: 20 | AA2: 21 | AB2: 22 | AC2: 23 | AD2: 24 | AE2: 25 | AF2: 26 | AG2: 27 | AH2: 28 | AI2: 29 | AJ2: 30 | AK2: 31
A3: Birch | B3: 20 | C3: 46 | D3: 609 | E3: 554 | AL3: =E3-G3-H3-I3-J3-K3-L3-M3-N3-O3-P3-Q3-R3-S3-T3-U3-V3-W3-X3-Y3-Z3-AA3-AB3-AC3-AD3-AE3-AF3-AG3-AH3-AI3-AJ3-AK3 -> 554 | AM3: =B3*C3*D3*AL3/1000000000 -> 0.31039512
A4: Poplar | B4: 13 | C4: 80 | D4: 830 | E4: 173 | AL4: =E4-G4-H4-I4-J4-K4-L4-M4-N4-O4-P4-Q4-R4-S4-T4-U4-V4-W4-X4-Y4-Z4-AA4-AB4-AC4-AD4-AE4-AF4-AG4-AH4-AI4-AJ4-AK4 -> 173 | AM4: =B4*C4*D4*AL4/1000000000 -> 0.1493336
A5: Poplar | B5: 13 | C5: 80 | D5: 640 | E5: 220 | AL5: =E5-G5-H5-I5-J5-K5-L5-M5-N5-O5-P5-Q5-R5-S5-T5-U5-V5-W5-X5-Y5-Z5-AA5-AB5-AC5-AD5-AE5-AF5-AG5-AH5-AI5-AJ5-AK5 -> 220 | AM5: =B5*C5*D5*AL5/1000000000 -> 0.146432
A6: Poplar | B6: 13.7 | C6: 1080 | D6: 950 | E6: 17 | AL6: =E6-G6-H6-I6-J6-K6-L6-M6-N6-O6-P6-Q6-R6-S6-T6-U6-V6-W6-X6-Y6-Z6-AA6-AB6-AC6-AD6-AE6-AF6-AG6-AH6-AI6-AJ6-AK6 -> 17 | AM6: =B6*C6*D6*AL6/1000000000 -> 0.2389554
A7: Poplar | B7: 13.7 | C7: 162 | D7: 460 | E7: 210 | AL7: =E7-G7-H7-I7-J7-K7-L7-M7-N7-O7-P7-Q7-R7-S7-T7-U7-V7-W7-X7-Y7-Z7-AA7-AB7-AC7-AD7-AE7-AF7-AG7-AH7-AI7-AJ7-AK7 -> 210 | AM7: =B7*C7*D7*AL7/1000000000 -> 0.21439404
A8: Rubber | B8: 15.9 | C8: 161.9 | D8: 480 | E8: 120 | AL8: =E8-G8-H8-I8-J8-K8-L8-M8-N8-O8-P8-Q8-R8-S8-T8-U8-V8-W8-X8-Y8-Z8-AA8-AB8-AC8-AD8-AE8-AF8-AG8-AH8-AI8-AJ8-AK8 -> 120 | AM8: =B8*C8*D8*AL8/1000000000 -> 0.1482745
A9: Rubber | B9: 15.9 | C9: 161.9 | D9: 700 | E9: 78 | AL9: =E9-G9-H9-I9-J9-K9-L9-M9-N9-O9-P9-Q9-R9-S9-T9-U9-V9-W9-X9-Y9-Z9-AA9-AB9-AC9-AD9-AE9-AF9-AG9-AH9-AI9-AJ9-AK9 -> 78 | AM9: =B9*C9*D9*AL9/1000000000 -> 0.14055187
A10: Rubber | B10: 15.9 | C10: 161.9 | D10: 540 | E10: 120 | AL10: =E10-G10-H10-I10-J10-K10-L10-M10-N10-O10-P10-Q10-R10-S10-T10-U10-V10-W10-X10-Y10-Z10-AA10-AB10-AC10-AD10-AE10-AF10-AG10-AH10-AI10-AJ10-AK10 -> 120 | AM10: =B10*C10*D10*AL10/1000000000 -> 0.16680881
A11: Poplar | B11: 12.7 | C11: 203.2 | D11: 523.6 | E11: 376 | AL11: =E11-G11-H11-I11-J11-K11-L11-M11-N11-O11-P11-Q11-R11-S11-T11-U11-V11-W11-X11-Y11-Z11-AA11-AB11-AC11-AD11-AE11-AF11-AG11-AH11-AI11-AJ11-AK11 -> 376 | AM11: =B11*C11*D11*AL11/1000000000 -> 0.50805989
A12: Rubber | B12: 15.9 | C12: 161.9 | D12: 444.5 | E12: 150 | AL12: =E12-G12-H12-I12-J12-K12-L12-M12-N12-O12-P12-Q12-R12-S12-T12-U12-V12-W12-X12-Y12-Z12-AA12-AB12-AC12-AD12-AE12-AF12-AG12-AH12-AI12-AJ12-AK12 -> 150 | AM12: =B12*C12*D12*AL12/1000000000 -> 0.17163545
A13: Rubber | B13: 15.9 | C13: 161.9 | D13: 676.3 | E13: 40 | AL13: =E13-G13-H13-I13-J13-K13-L13-M13-N13-O13-P13-Q13-R13-S13-T13-U13-V13-W13-X13-Y13-Z13-AA13-AB13-AC13-AD13-AE13-AF13-AG13-AH13-AI13-AJ13-AK13 -> 40 | AM13: =B13*C13*D13*AL13/1000000000 -> 0.069637529
A14: Rubber | B14: 15.9 | C14: 161.9 | D14: 447.7 | E14: 70 | AL14: =E14-G14-H14-I14-J14-K14-L14-M14-N14-O14-P14-Q14-R14-S14-T14-U14-V14-W14-X14-Y14-Z14-AA14-AB14-AC14-AD14-AE14-AF14-AG14-AH14-AI14-AJ14-AK14 -> 70 | AM14: =B14*C14*D14*AL14/1000000000 -> 0.080673167
... A158: Birch | B158: 12 | C158: 41.3 | D158: 850 | E158: 800 | AL158: =E158-G158-H158-I158-J158-K158-L158-M158-N158-O158-P158-Q158-R158-S158-T158-U158-V158-W158-X158-Y158-Z158-AA158-AB158-AC158-AD158-AE158-AF158-AG158-AH158-AI158-AJ158-AK158 -> 800 | AM158: =B158*C158*D158*AL158/1000000000 -> 0.337008
A159: Birch | B159: 12 | C159: 41.3 | D159: 850 | E159: 1800 | P159: 857 | AL159: =E159-G159-H159-I159-J159-K159-L159-M159-N159-O159-P159-Q159-R159-S159-T159-U159-V159-W159-X159-Y159-Z159-AA159-AB159-AC159-AD159-AE159-AF159-AG159-AH159-AI159-AJ159-AK159 -> 943 | AM159: =B159*C159*D159*AL159/1000000000 -> 0.39724818
A160: Birch | B160: 12 | C160: 41.3 | D160: 850 | E160: 1500 | AL160: =E160-G160-H160-I160-J160-K160-L160-M160-N160-O160-P160-Q160-R160-S160-T160-U160-V160-W160-X160-Y160-Z160-AA160-AB160-AC160-AD160-AE160-AF160-AG160-AH160-AI160-AJ160-AK160 -> 1500 | AM160: =B160*C160*D160*AL160/1000000000 -> 0.63189
A161: Birch | B161: 12 | C161: 41.3 | D161: 700 | E161: 1500 | AL161: =E161-G161-H161-I161-J161-K161-L161-M161-N161-O161-P161-Q161-R161-S161-T161-U161-V161-W161-X161-Y161-Z161-AA161-AB161-AC161-AD161-AE161-AF161-AG161-AH161-AI161-AJ161-AK161 -> 1500 | AM161: =B161*C161*D161*AL161/1000000000 -> 0.52038
A162: Birch | B162: 12 | C162: 41.3 | D162: 700 | E162: 1800 | AL162: =E162-G162-H162-I162-J162-K162-L162-M162-N162-O162-P162-Q162-R162-S162-T162-U162-V162-W162-X162-Y162-Z162-AA162-AB162-AC162-AD162-AE162-AF162-AG162-AH162-AI162-AJ162-AK162 -> 1800 | AM162: =B162*C162*D162*AL162/1000000000 -> 0.624456
A163: Birch | B163: 12 | C163: 41.3 | D163: 700 | E163: 760 | AL163: =E163-G163-H163-I163-J163-K163-L163-M163-N163-O163-P163-Q163-R163-S163-T163-U163-V163-W163-X163-Y163-Z163-AA163-AB163-AC163-AD163-AE163-AF163-AG163-AH163-AI163-AJ163-AK163 -> 760 | AM163: =B163*C163*D163*AL163/1000000000 -> 0.2636592
A164: Birch | B164: 12 | C164: 41.3 | D164: 420 | E164: 1500 | AL164: =E164-G164-H164-I164-J164-K164-L164-M164-N164-O164-P164-Q164-R164-S164-T164-U164-V164-W164-X164-Y164-Z164-AA164-AB164-AC164-AD164-AE164-AF164-AG164-AH164-AI164-AJ164-AK164 -> 1500 | AM164: =B164*C164*D164*AL164/1000000000 -> 0.312228
A165: Birch | B165: 12 | C165: 41.3 | D165: 350 | E165: 2200 | AL165: =E165-G165-H165-I165-J165-K165-L165-M165-N165-O165-P165-Q165-R165-S165-T165-U165-V165-W165-X165-Y165-Z165-AA165-AB165-AC165-AD165-AE165-AF165-AG165-AH165-AI165-AJ165-AK165 -> 2200 | AM165: =B165*C165*D165*AL165/1000000000 -> 0.381612
A166: Birch | B166: 12 | C166: 36 | D166: 410 | E166: 1545 | AL166: =E166-G166-H166-I166-J166-K166-L166-M166-N166-O166-P166-Q166-R166-S166-T166-U166-V166-W166-X166-Y166-Z166-AA166-AB166-AC166-AD166-AE166-AF166-AG166-AH166-AI166-AJ166-AK166 -> 1545 | AM166: =B166*C166*D166*AL166/1000000000 -> 0.2736504
A167: Birch | B167: 12 | C167: 31.8 | D167: 630 | E167: 600 | AL167: =E167-G167-H167-I167-J167-K167-L167-M167-N167-O167-P167-Q167-R167-S167-T167-U167-V167-W167-X167-Y167-Z167-AA167-AB167-AC167-AD167-AE167-AF167-AG167-AH167-AI167-AJ167-AK167 -> 600 | AM167: =B167*C167*D167*AL167/1000000000 -> 0.1442448
A168: Birch | B168: 12 | C168: 31.8 | D168: 630 | E168: 490 | AL168: =E168-G168-H168-I168-J168-K168-L168-M168-N168-O168-P168-Q168-R168-S168-T168-U168-V168-W168-X168-Y168-Z168-AA168-AB168-AC168-AD168-AE168-AF168-AG168-AH168-AI168-AJ168-AK168 -> 490 | AM168: =B168*C168*D168*AL168/1000000000 -> 0.11779992
A169: Birch | B169: 12 | C169: 31.8 | D169: 520 | E169: 3800 | AL169: =E169-G169-H169-I169-J169-K169-L169-M169-N169-O169-P169-Q169-R169-S169-T169-U169-V169-W169-X169-Y169-Z169-AA169-AB169-AC169-AD169-AE169-AF169-AG169-AH169-AI169-AJ169-AK169 -> 3800 | AM169: =B169*C169*D169*AL169/1000000000 -> 0.7540416
A170: Birch | B170: 12 | C170: 31.8 | D170: 520 | E170: 620 | AL170: =E170-G170-H170-I170-J170-K170-L170-M170-N170-O170-P170-Q170-R170-S170-T170-U170-V170-W170-X170-Y170-Z170-AA170-AB170-AC170-AD170-AE170-AF170-AG170-AH170-AI170-AJ170-AK170 -> 620 | AM170: =B170*C170*D170*AL170/1000000000 -> 0.12302784
A171: Birch | B171: 12 | C171: 31.8 | D171: 520 | E171: 1200 | AL171: =E171-G171-H171-I171-J171-K171-L171-M171-N171-O171-P171-Q171-R171-S171-T171-U171-V171-W171-X171-Y171-Z171-AA171-AB171-AC171-AD171-AE171-AF171-AG171-AH171-AI171-AJ171-AK171 -> 1200 | AM171: =B171*C171*D171*AL171/1000000000 -> 0.2381184
A172: Birch | B172: 12 | C172: 31.8 | D172: 520 | E172: 2400 | AC172: 1617 | AL172: =E172-G172-H172-I172-J172-K172-L172-M172-N172-O172-P172-Q172-R172-S172-T172-U172-V172-W172-X172-Y172-Z172-AA172-AB172-AC172-AD172-AE172-AF172-AG172-AH172-AI172-AJ172-AK172 -> 783 | AM172: =B172*C172*D172*AL172/1000000000 -> 0.15537226
A173: Birch | B173: 12 | C173: 31.8 | D173: 520 | E173: 600 | AL173: =E173-G173-H173-I173-J173-K173-L173-M173-N173-O173-P173-Q173-R173-S173-T173-U173-V173-W173-X173-Y173-Z173-AA173-AB173-AC173-AD173-AE173-AF173-AG173-AH173-AI173-AJ173-AK173 -> 600 | AM173: =B173*C173*D173*AL173/1000000000 -> 0.1190592
A174: Birch | B174: 12 | C174: 31.8 | D174: 520 | E174: 2400 | AL174: =E174-G174-H174-I174-J174-K174-L174-M174-N174-O174-P174-Q174-R174-S174-T174-U174-V174-W174-X174-Y174-Z174-AA174-AB174-AC174-AD174-AE174-AF174-AG174-AH174-AI174-AJ174-AK174 -> 2400 | AM174: =B174*C174*D174*AL174/1000000000 -> 0.4762368
A175: Birch | B175: 12 | C175: 79 | D175: 510 | E175: 600 | AL175: =E175-G175-H175-I175-J175-K175-L175-M175-N175-O175-P175-Q175-R175-S175-T175-U175-V175-W175-X175-Y175-Z175-AA175-AB175-AC175-AD175-AE175-AF175-AG175-AH175-AI175-AJ175-AK175 -> 600 | AM175: =B175*C175*D175*AL175/1000000000 -> 0.290088
A176: Birch | B176: 12 | C176: 79 | D176: 510 | E176: 600 | AL176: =E176-G176-H176-I176-J176-K176-L176-M176-N176-O176-P176-Q176-R176-S176-T176-U176-V176-W176-X176-Y176-Z176-AA176-AB176-AC176-AD176-AE176-AF176-AG176-AH176-AI176-AJ176-AK176 -> 600 | AM176: =B176*C176*D176*AL176/1000000000 -> 0.290088
A177: Birch | B177: 16 | C177: 254 | D177: 520.7 | E177: 470 | AL177: =E177-G177-H177-I177-J177-K177-L177-M177-N177-O177-P177-Q177-R177-S177-T177-U177-V177-W177-X177-Y177-Z177-AA177-AB177-AC177-AD177-AE177-AF177-AG177-AH177-AI177-AJ177-AK177 -> 470 | AM177: =B177*C177*D177*AL177/1000000000 -> 0.99457866
A178: Birch | B178: 16 | C178: 254 | D178: 520.7 | E178: 390 | AL178: =E178-G178-H178-I178-J178-K178-L178-M178-N178-O178-P178-Q178-R178-S178-T178-U178-V178-W178-X178-Y178-Z178-AA178-AB178-AC178-AD178-AE178-AF178-AG178-AH178-AI178-AJ178-AK178 -> 390 | AM178: =B178*C178*D178*AL178/1000000000 -> 0.82528867
A179: Birch | B179: 16 | C179: 254 | D179: 520.7 | E179: 540 | AL179: =E179-G179-H179-I179-J179-K179-L179-M179-N179-O179-P179-Q179-R179-S179-T179-U179-V179-W179-X179-Y179-Z179-AA179-AB179-AC179-AD179-AE179-AF179-AG179-AH179-AI179-AJ179-AK179 -> 540 | AM179: =B179*C179*D179*AL179/1000000000 -> 1.1427074
A180: Birch | B180: 16 | C180: 254 | D180: 520.7 | E180: 540 | AL180: =E180-G180-H180-I180-J180-K180-L180-M180-N180-O180-P180-Q180-R180-S180-T180-U180-V180-W180-X180-Y180-Z180-AA180-AB180-AC180-AD180-AE180-AF180-AG180-AH180-AI180-AJ180-AK180 -> 540 | AM180: =B180*C180*D180*AL180/1000000000 -> 1.1427074
A181: Birch | B181: 20 | C181: 52 | D181: 690 | E181: 1000 | AL181: =E181-G181-H181-I181-J181-K181-L181-M181-N181-O181-P181-Q181-R181-S181-T181-U181-V181-W181-X181-Y181-Z181-AA181-AB181-AC181-AD181-AE181-AF181-AG181-AH181-AI181-AJ181-AK181 -> 1000 | AM181: =B181*C181*D181*AL181/1000000000 -> 0.7176
A182: Birch | B182: 20 | C182: 52 | D182: 690 | E182: 800 | AB182: 210 | AL182: =E182-G182-H182-I182-J182-K182-L182-M182-N182-O182-P182-Q182-R182-S182-T182-U182-V182-W182-X182-Y182-Z182-AA182-AB182-AC182-AD182-AE182-AF182-AG182-AH182-AI182-AJ182-AK182 -> 590 | AM182: =B182*C182*D182*AL182/1000000000 -> 0.423384 | AP182: =AL182*AN182*33.8783 -> 0
A183: Birch | B183: 20 | C183: 52 | D183: 830 | E183: 1010 | AL183: =E183-G183-H183-I183-J183-K183-L183-M183-N183-O183-P183-Q183-R183-S183-T183-U183-V183-W183-X183-Y183-Z183-AA183-AB183-AC183-AD183-AE183-AF183-AG183-AH183-AI183-AJ183-AK183 -> 1010 | AM183: =B183*C183*D183*AL183/1000000000 -> 0.871832 | AP183: =AL183*AN183*33.8783 -> 0
...

Sheet VIETNAM
B1: T | C1: W | D1: L | E1: PCS | F1: INV | G1: IN DATE | H1: OUT DATE - JULY | AM1: BALANCE | AN1: m3 | AO1: USD/PCS | AP1: USD/m3 | AQ1: USD to THB
H2: 1 | I2: 2 | J2: 3 | K2: 4 | L2: 5 | M2: 6 | N2: 7 | O2: 8 | P2: 9 | Q2: 10 | R2: 11 | S2: 12 | T2: 13 | U2: 14 | V2: 15 | W2: 16 | X2: 17 | Y2: 18 | Z2: 19 | AA2: 20 | AB2: 21 | AC2: 22 | AD2: 23 | AE2: 24 | AF2: 25 | AG2: 26 | AH2: 27 | AI2: 28 | AJ2: 29 | AK2: 30 | AL2: 31
A3: MDF-BIRCH | B3: 5.3 | C3: 1220 | D3: 2440 | E3: 137 | F3: GW-TM260207 | G3: 46098 | AM3: =E3-H3-I3-J3-K3-L3-M3-N3-O3-P3-Q3-R3-S3-T3-U3-V3-W3-X3-Y3-Z3-AA3-AB3-AC3-AD3-AE3-AF3-AG3-AH3-AI3-AJ3-AK3-AL3 -> 137 | AN3: =B3*C3*D3*AM3/1000000000 -> 2.1614545 | AO3: =15.5*31.3303 -> 485.61965 | AQ3: =AO3*AM3 -> 66529.892
A4: MDF-BIRCH | B4: 5.3 | C4: 1220 | D4: 2440 | E4: 170 | F4: GW-TM260207 | G4: 46098 | AM4: =E4-H4-I4-J4-K4-L4-M4-N4-O4-P4-Q4-R4-S4-T4-U4-V4-W4-X4-Y4-Z4-AA4-AB4-AC4-AD4-AE4-AF4-AG4-AH4-AI4-AJ4-AK4-AL4 -> 170 | AN4: =B4*C4*D4*AM4/1000000000 -> 2.6820968 | AO4: =15.5*31.3303 -> 485.61965 | AQ4: =AO4*AM4 -> 82555.341
A5: MDF-BIRCH | B5: 5.3 | C5: 1220 | D5: 2440 | E5: 170 | F5: GW-TM260207 | G5: 46098 | AM5: =E5-H5-I5-J5-K5-L5-M5-N5-O5-P5-Q5-R5-S5-T5-U5-V5-W5-X5-Y5-Z5-AA5-AB5-AC5-AD5-AE5-AF5-AG5-AH5-AI5-AJ5-AK5-AL5 -> 170 | AN5: =B5*C5*D5*AM5/1000000000 -> 2.6820968 | AO5: =15.5*31.3303 -> 485.61965 | AQ5: =AO5*AM5 -> 82555.341
A6: MDF-BIRCH | B6: 5.3 | C6: 1220 | D6: 2440 | E6: 170 | F6: GW-TM260207 | G6: 46098 | AM6: =E6-H6-I6-J6-K6-L6-M6-N6-O6-P6-Q6-R6-S6-T6-U6-V6-W6-X6-Y6-Z6-AA6-AB6-AC6-AD6-AE6-AF6-AG6-AH6-AI6-AJ6-AK6-AL6 -> 170 | AN6: =B6*C6*D6*AM6/1000000000 -> 2.6820968 | AO6: =15.5*31.3303 -> 485.61965 | AQ6: =AO6*AM6 -> 82555.341
A7: MDF-BIRCH | B7: 5.3 | C7: 1220 | D7: 2440 | E7: 170 | F7: GW-TM260207 | G7: 46098 | AM7: =E7-H7-I7-J7-K7-L7-M7-N7-O7-P7-Q7-R7-S7-T7-U7-V7-W7-X7-Y7-Z7-AA7-AB7-AC7-AD7-AE7-AF7-AG7-AH7-AI7-AJ7-AK7-AL7 -> 170 | AN7: =B7*C7*D7*AM7/1000000000 -> 2.6820968 | AO7: =15.5*31.3303 -> 485.61965 | AQ7: =AO7*AM7 -> 82555.341
A8: MDF-BIRCH | B8: 5.3 | C8: 1220 | D8: 2440 | E8: 170 | F8: GW-TM260207 | G8: 46098 | AM8: =E8-H8-I8-J8-K8-L8-M8-N8-O8-P8-Q8-R8-S8-T8-U8-V8-W8-X8-Y8-Z8-AA8-AB8-AC8-AD8-AE8-AF8-AG8-AH8-AI8-AJ8-AK8-AL8 -> 170 | AN8: =B8*C8*D8*AM8/1000000000 -> 2.6820968 | AO8: =15.5*31.3303 -> 485.61965 | AQ8: =AO8*AM8 -> 82555.341
A9: MDF-BIRCH | B9: 5.3 | C9: 1220 | D9: 2440 | E9: 8 | F9: GW-TM260207 | G9: 46098 | AM9: =E9-H9-I9-J9-K9-L9-M9-N9-O9-P9-Q9-R9-S9-T9-U9-V9-W9-X9-Y9-Z9-AA9-AB9-AC9-AD9-AE9-AF9-AG9-AH9-AI9-AJ9-AK9-AL9 -> 8 | AN9: =B9*C9*D9*AM9/1000000000 -> 0.12621632 | AO9: =15.5*31.3303 -> 485.61965 | AQ9: =AO9*AM9 -> 3884.9572
A10: PLYWOOD-BIRCH | B10: 6 | C10: 1220 | D10: 2440 | E10: 166 | F10: GW-TM260207 | G10: 46098 | AM10: =E10-H10-I10-J10-K10-L10-M10-N10-O10-P10-Q10-R10-S10-T10-U10-V10-W10-X10-Y10-Z10-AA10-AB10-AC10-AD10-AE10-AF10-AG10-AH10-AI10-AJ10-AK10-AL10 -> 166 | AN10: =B10*C10*D10*AM10/1000000000 -> 2.9648928 | AO10: =9.8*31.3303 -> 307.03694 | AQ10: =AO10*AM10 -> 50968.132
A11: PLYWOOD-BIRCH | B11: 9 | C11: 1220 | D11: 2440 | E11: 105 | F11: GW-TM260207 | G11: 46098 | AM11: =E11-H11-I11-J11-K11-L11-M11-N11-O11-P11-Q11-R11-S11-T11-U11-V11-W11-X11-Y11-Z11-AA11-AB11-AC11-AD11-AE11-AF11-AG11-AH11-AI11-AJ11-AK11-AL11 -> 105 | AN11: =B11*C11*D11*AM11/1000000000 -> 2.813076 | AO11: =13*31.3303 -> 407.2939 | AQ11: =AO11*AM11 -> 42765.859
A12: PLYWOOD-BIRCH | B12: 18 | C12: 1220 | D12: 2440 | E12: 53 | F12: GW-TM260207 | G12: 46098 | AM12: =E12-H12-I12-J12-K12-L12-M12-N12-O12-P12-Q12-R12-S12-T12-U12-V12-W12-X12-Y12-Z12-AA12-AB12-AC12-AD12-AE12-AF12-AG12-AH12-AI12-AJ12-AK12-AL12 -> 53 | AN12: =B12*C12*D12*AM12/1000000000 -> 2.8398672 | AO12: =13*31.3303 -> 407.2939 | AQ12: =AO12*AM12 -> 21586.577
A13: PLYWOOD-BIRCH | B13: 18 | C13: 1220 | D13: 2440 | E13: 53 | F13: GW-TM260207 | G13: 46098 | AM13: =E13-H13-I13-J13-K13-L13-M13-N13-O13-P13-Q13-R13-S13-T13-U13-V13-W13-X13-Y13-Z13-AA13-AB13-AC13-AD13-AE13-AF13-AG13-AH13-AI13-AJ13-AK13-AL13 -> 53 | AN13: =B13*C13*D13*AM13/1000000000 -> 2.8398672 | AO13: =22.5*31.3303 -> 704.93175 | AQ13: =AO13*AM13 -> 37361.383
A14: PLYWOOD-BIRCH | B14: 5.3 | C14: 1220 | D14: 2440 | E14: 200 | F14: GW-TM260410 | G14: 46139 | AM14: =E14-H14-I14-J14-K14-L14-M14-N14-O14-P14-Q14-R14-S14-T14-U14-V14-W14-X14-Y14-Z14-AA14-AB14-AC14-AD14-AE14-AF14-AG14-AH14-AI14-AJ14-AK14-AL14 -> 200 | AN14: =B14*C14*D14*AM14/1000000000 -> 3.155408 | AO14: =15.5*31.3303 -> 485.61965 | AQ14: =AO14*AM14 -> 97123.93
A15: PLYWOOD-BIRCH | B15: 5.3 | C15: 1220 | D15: 2440 | E15: 200 | F15: GW-TM260410 | G15: 46139 | AM15: =E15-H15-I15-J15-K15-L15-M15-N15-O15-P15-Q15-R15-S15-T15-U15-V15-W15-X15-Y15-Z15-AA15-AB15-AC15-AD15-AE15-AF15-AG15-AH15-AI15-AJ15-AK15-AL15 -> 200 | AN15: =B15*C15*D15*AM15/1000000000 -> 3.155408 | AO15: =15.5*31.3303 -> 485.61965 | AQ15: =AO15*AM15 -> 97123.93
A16: PLYWOOD-BIRCH | B16: 12 | C16: 1220 | D16: 2440 | E16: 1400 | F16: GW-TM260710 | G16: 46226 | AE16: 200 | AH16: 200 | AK16: 200 | AM16: =E16-H16-I16-J16-K16-L16-M16-N16-O16-P16-Q16-R16-S16-T16-U16-V16-W16-X16-Y16-Z16-AA16-AB16-AC16-AD16-AE16-AF16-AG16-AH16-AI16-AJ16-AK16-AL16 -> 800 | AN16: =B16*C16*D16*AM16/1000000000 -> 28.57728 | AP16: 20.2 | AQ16: =AP16*AM16*32.8679 -> 531145.26
G18: MDF-BIRCH | AN18: =SUMIF(A3:A16, "MDF-BIRCH", AN3:AN16) -> 15.698155 | AQ18: =SUMIF(A3:A16, "MDF-BIRCH", AQ3:AQ16) -> 483191.55 | AR18: =AQ18/AN18 -> 30780.15
G19: PLYWOOD-BIRCH | AN19: =SUMIF(A3:A16, "PLYWOOD-BIRCH", AN3:AN16) -> 46.345799 | AQ19: =SUMIF(A3:A16, "PLYWOOD-BIRCH", AQ3:AQ16) -> 878075.07 | AR19: =AQ19/AN19 -> 18946.163
AN20: =SUM(AN18:AN19) -> 62.043954 | AQ20: =SUM(AQ18:AQ19) -> 1361266.6

Sheet CT1
A1: Out Cutting
A2: Date In | B2: Decription | C2: Actual size | D2: Size | G2: Quantity | H2: Rate | I2: M3 ลูกบาศก์ | J2: F3 ลูกบาศก์ | K2: Price | L2: Amount | M2: Remark
C3: T(mm) | D3: T(mm) | E3: W | F3: L | H3: （%）
A4: Stock | D4: 15.875 | E4: =2*25.4 -> 50.8 | F4: 390 | G4: 1255 | I4: =D4*E4*F4*G4/1000000000 -> 0.39471695 | J4: =I4*35.315 -> 13.939429 | K4: 15000 | L4: =I4*K4 -> 5920.7543 | N4: พี่ไหน
A5: Stock | D5: 15.875 | E5: =2.5*25.4 -> 63.5 | F5: 490 | G5: 14270 | I5: =D5*E5*F5*G5/1000000000 -> 7.0486754 | J5: =I5*35.315 -> 248.92397 | K5: 15000 | L5: =I5*K5 -> 105730.13 | N5: พี่ไหน
A6: Stock | D6: 15.875 | E6: =3*25.4 -> 76.2 | F6: 490 | G6: 1280 | I6: =D6*E6*F6*G6/1000000000 -> 0.75870816 | J6: =I6*35.315 -> 26.793779 | K6: 15000 | L6: =I6*K6 -> 11380.622 | N6: พี่ไหน
A7: Stock | D7: 15.875 | E7: =3*25.4 -> 76.2 | F7: 490 | G7: 190 | I7: =D7*E7*F7*G7/1000000000 -> 0.11262074 | J7: =I7*35.315 -> 3.9772015 | K7: 15000 | L7: =I7*K7 -> 1689.3111 | N7: พี่ไหน
A8: Stock | D8: 15.875 | E8: =2*25.4 -> 50.8 | F8: 320 | G8: 2400 | I8: =D8*E8*F8*G8/1000000000 -> 0.6193536 | J8: =I8*35.315 -> 21.872472 | K8: 15000 | L8: =I8*K8 -> 9290.304 | N8: พี่ไหน
A9: Stock | D9: 15.875 | E9: =2*25.4 -> 50.8 | F9: 320 | G9: 800 | I9: =D9*E9*F9*G9/1000000000 -> 0.2064512 | J9: =I9*35.315 -> 7.2908241 | K9: 15000 | L9: =I9*K9 -> 3096.768 | N9: พี่ไหน
A10: Stock | D10: 15.875 | E10: =3*25.4 -> 76.2 | F10: 490 | G10: 1240 | I10: =D10*E10*F10*G10/1000000000 -> 0.73499853 | J10: =I10*35.315 -> 25.956473 | K10: 15000 | L10: =I10*K10 -> 11024.978 | N10: พี่ไหน
